[2016-06-15 19:56:00,741] [ERROR] base : Internal Server Error: /
Traceback (most recent call last):
  File "/Users/apple/code/python/virtualsys/blog/lib/python3.5/site-packages/django/db/backends/utils.py", line 64, in execute
    return self.cursor.execute(sql, params)
  File "/Users/apple/code/python/virtualsys/blog/lib/python3.5/site-packages/django/db/backends/sqlite3/base.py", line 318, in execute
    return Database.Cursor.execute(self, query, params)
sqlite3.OperationalError: no such table: blog_article

The above exception was the direct cause of the following exception:

Traceback (most recent call last):
  File "/Users/apple/code/python/virtualsys/blog/lib/python3.5/site-packages/django/core/handlers/base.py", line 132, in get_response
    response = wrapped_callback(request, *callback_args, **callback_kwargs)
  File "/Users/apple/code/python/virtualsys/blog/lib/python3.5/site-packages/django/views/generic/base.py", line 71, in view
    return self.dispatch(request, *args, **kwargs)
  File "/Users/apple/code/python/virtualsys/blog/lib/python3.5/site-packages/django/views/generic/base.py", line 89, in dispatch
    return handler(request, *args, **kwargs)
  File "/Users/apple/code/python/virtualsys/blog/lib/python3.5/site-packages/django/views/generic/list.py", line 174, in get
    context = self.get_context_data()
  File "/Users/apple/code/python/liuclblog/blog/views.py", line 73, in get_context_data
    return super(IndexView, self).get_context_data(**kwargs)
  File "/Users/apple/code/python/liuclblog/blog/views.py", line 36, in get_context_data
    context = super(BaseMixin, self).get_context_data(**kwargs)
  File "/Users/apple/code/python/virtualsys/blog/lib/python3.5/site-packages/django/views/generic/list.py", line 134, in get_context_data
    paginator, page, queryset, is_paginated = self.paginate_queryset(queryset, page_size)
  File "/Users/apple/code/python/virtualsys/blog/lib/python3.5/site-packages/django/views/generic/list.py", line 78, in paginate_queryset
    page = paginator.page(page_number)
  File "/Users/apple/code/python/virtualsys/blog/lib/python3.5/site-packages/django/core/paginator.py", line 50, in page
    number = self.validate_number(number)
  File "/Users/apple/code/python/virtualsys/blog/lib/python3.5/site-packages/django/core/paginator.py", line 39, in validate_number
    if number > self.num_pages:
  File "/Users/apple/code/python/virtualsys/blog/lib/python3.5/site-packages/django/core/paginator.py", line 86, in _get_num_pages
    if self.count == 0 and not self.allow_empty_first_page:
  File "/Users/apple/code/python/virtualsys/blog/lib/python3.5/site-packages/django/core/paginator.py", line 72, in _get_count
    self._count = self.object_list.count()
  File "/Users/apple/code/python/virtualsys/blog/lib/python3.5/site-packages/django/db/models/query.py", line 318, in count
    return self.query.get_count(using=self.db)
  File "/Users/apple/code/python/virtualsys/blog/lib/python3.5/site-packages/django/db/models/sql/query.py", line 464, in get_count
    number = obj.get_aggregation(using, ['__count'])['__count']
  File "/Users/apple/code/python/virtualsys/blog/lib/python3.5/site-packages/django/db/models/sql/query.py", line 445, in get_aggregation
    result = compiler.execute_sql(SINGLE)
  File "/Users/apple/code/python/virtualsys/blog/lib/python3.5/site-packages/django/db/models/sql/compiler.py", line 829, in execute_sql
    cursor.execute(sql, params)
  File "/Users/apple/code/python/virtualsys/blog/lib/python3.5/site-packages/django/db/backends/utils.py", line 79, in execute
    return super(CursorDebugWrapper, self).execute(sql, params)
  File "/Users/apple/code/python/virtualsys/blog/lib/python3.5/site-packages/django/db/backends/utils.py", line 64, in execute
    return self.cursor.execute(sql, params)
  File "/Users/apple/code/python/virtualsys/blog/lib/python3.5/site-packages/django/db/utils.py", line 97, in __exit__
    six.reraise(dj_exc_type, dj_exc_value, traceback)
  File "/Users/apple/code/python/virtualsys/blog/lib/python3.5/site-packages/django/utils/six.py", line 658, in reraise
    raise value.with_traceback(tb)
  File "/Users/apple/code/python/virtualsys/blog/lib/python3.5/site-packages/django/db/backends/utils.py", line 64, in execute
    return self.cursor.execute(sql, params)
  File "/Users/apple/code/python/virtualsys/blog/lib/python3.5/site-packages/django/db/backends/sqlite3/base.py", line 318, in execute
    return Database.Cursor.execute(self, query, params)
django.db.utils.OperationalError: no such table: blog_article
[2016-06-15 19:56:00,741] [ERROR] base : Internal Server Error: /
Traceback (most recent call last):
  File "/Users/apple/code/python/virtualsys/blog/lib/python3.5/site-packages/django/db/backends/utils.py", line 64, in execute
    return self.cursor.execute(sql, params)
  File "/Users/apple/code/python/virtualsys/blog/lib/python3.5/site-packages/django/db/backends/sqlite3/base.py", line 318, in execute
    return Database.Cursor.execute(self, query, params)
sqlite3.OperationalError: no such table: blog_article

The above exception was the direct cause of the following exception:

Traceback (most recent call last):
  File "/Users/apple/code/python/virtualsys/blog/lib/python3.5/site-packages/django/core/handlers/base.py", line 132, in get_response
    response = wrapped_callback(request, *callback_args, **callback_kwargs)
  File "/Users/apple/code/python/virtualsys/blog/lib/python3.5/site-packages/django/views/generic/base.py", line 71, in view
    return self.dispatch(request, *args, **kwargs)
  File "/Users/apple/code/python/virtualsys/blog/lib/python3.5/site-packages/django/views/generic/base.py", line 89, in dispatch
    return handler(request, *args, **kwargs)
  File "/Users/apple/code/python/virtualsys/blog/lib/python3.5/site-packages/django/views/generic/list.py", line 174, in get
    context = self.get_context_data()
  File "/Users/apple/code/python/liuclblog/blog/views.py", line 73, in get_context_data
    return super(IndexView, self).get_context_data(**kwargs)
  File "/Users/apple/code/python/liuclblog/blog/views.py", line 36, in get_context_data
    context = super(BaseMixin, self).get_context_data(**kwargs)
  File "/Users/apple/code/python/virtualsys/blog/lib/python3.5/site-packages/django/views/generic/list.py", line 134, in get_context_data
    paginator, page, queryset, is_paginated = self.paginate_queryset(queryset, page_size)
  File "/Users/apple/code/python/virtualsys/blog/lib/python3.5/site-packages/django/views/generic/list.py", line 78, in paginate_queryset
    page = paginator.page(page_number)
  File "/Users/apple/code/python/virtualsys/blog/lib/python3.5/site-packages/django/core/paginator.py", line 50, in page
    number = self.validate_number(number)
  File "/Users/apple/code/python/virtualsys/blog/lib/python3.5/site-packages/django/core/paginator.py", line 39, in validate_number
    if number > self.num_pages:
  File "/Users/apple/code/python/virtualsys/blog/lib/python3.5/site-packages/django/core/paginator.py", line 86, in _get_num_pages
    if self.count == 0 and not self.allow_empty_first_page:
  File "/Users/apple/code/python/virtualsys/blog/lib/python3.5/site-packages/django/core/paginator.py", line 72, in _get_count
    self._count = self.object_list.count()
  File "/Users/apple/code/python/virtualsys/blog/lib/python3.5/site-packages/django/db/models/query.py", line 318, in count
    return self.query.get_count(using=self.db)
  File "/Users/apple/code/python/virtualsys/blog/lib/python3.5/site-packages/django/db/models/sql/query.py", line 464, in get_count
    number = obj.get_aggregation(using, ['__count'])['__count']
  File "/Users/apple/code/python/virtualsys/blog/lib/python3.5/site-packages/django/db/models/sql/query.py", line 445, in get_aggregation
    result = compiler.execute_sql(SINGLE)
  File "/Users/apple/code/python/virtualsys/blog/lib/python3.5/site-packages/django/db/models/sql/compiler.py", line 829, in execute_sql
    cursor.execute(sql, params)
  File "/Users/apple/code/python/virtualsys/blog/lib/python3.5/site-packages/django/db/backends/utils.py", line 79, in execute
    return super(CursorDebugWrapper, self).execute(sql, params)
  File "/Users/apple/code/python/virtualsys/blog/lib/python3.5/site-packages/django/db/backends/utils.py", line 64, in execute
    return self.cursor.execute(sql, params)
  File "/Users/apple/code/python/virtualsys/blog/lib/python3.5/site-packages/django/db/utils.py", line 97, in __exit__
    six.reraise(dj_exc_type, dj_exc_value, traceback)
  File "/Users/apple/code/python/virtualsys/blog/lib/python3.5/site-packages/django/utils/six.py", line 658, in reraise
    raise value.with_traceback(tb)
  File "/Users/apple/code/python/virtualsys/blog/lib/python3.5/site-packages/django/db/backends/utils.py", line 64, in execute
    return self.cursor.execute(sql, params)
  File "/Users/apple/code/python/virtualsys/blog/lib/python3.5/site-packages/django/db/backends/sqlite3/base.py", line 318, in execute
    return Database.Cursor.execute(self, query, params)
django.db.utils.OperationalError: no such table: blog_article
[2016-06-16 09:29:47,306] [ERROR] base : Internal Server Error: /
Traceback (most recent call last):
  File "/Users/apple/code/python/virtualsys/blog/lib/python3.5/site-packages/django/core/urlresolvers.py", line 394, in urlconf_module
    return self._urlconf_module
AttributeError: 'RegexURLResolver' object has no attribute '_urlconf_module'

During handling of the above exception, another exception occurred:

Traceback (most recent call last):
  File "/Users/apple/code/python/virtualsys/blog/lib/python3.5/site-packages/django/core/handlers/base.py", line 119, in get_response
    resolver_match = resolver.resolve(request.path_info)
  File "/Users/apple/code/python/virtualsys/blog/lib/python3.5/site-packages/django/core/urlresolvers.py", line 366, in resolve
    for pattern in self.url_patterns:
  File "/Users/apple/code/python/virtualsys/blog/lib/python3.5/site-packages/django/core/urlresolvers.py", line 402, in url_patterns
    patterns = getattr(self.urlconf_module, "urlpatterns", self.urlconf_module)
  File "/Users/apple/code/python/virtualsys/blog/lib/python3.5/site-packages/django/core/urlresolvers.py", line 396, in urlconf_module
    self._urlconf_module = import_module(self.urlconf_name)
  File "/Users/apple/code/python/virtualsys/blog/lib/python3.5/importlib/__init__.py", line 126, in import_module
    return _bootstrap._gcd_import(name[level:], package, level)
  File "<frozen importlib._bootstrap>", line 986, in _gcd_import
  File "<frozen importlib._bootstrap>", line 969, in _find_and_load
  File "<frozen importlib._bootstrap>", line 958, in _find_and_load_unlocked
  File "<frozen importlib._bootstrap>", line 673, in _load_unlocked
  File "<frozen importlib._bootstrap_external>", line 662, in exec_module
  File "<frozen importlib._bootstrap>", line 222, in _call_with_frames_removed
  File "/Users/apple/code/python/liuclblog/liucl_blog/urls.py", line 68, in <module>
    url(r'', include('blog.urls')),
  File "/Users/apple/code/python/virtualsys/blog/lib/python3.5/site-packages/django/conf/urls/__init__.py", line 33, in include
    urlconf_module = import_module(urlconf_module)
  File "/Users/apple/code/python/virtualsys/blog/lib/python3.5/importlib/__init__.py", line 126, in import_module
    return _bootstrap._gcd_import(name[level:], package, level)
  File "<frozen importlib._bootstrap>", line 986, in _gcd_import
  File "<frozen importlib._bootstrap>", line 969, in _find_and_load
  File "<frozen importlib._bootstrap>", line 958, in _find_and_load_unlocked
  File "<frozen importlib._bootstrap>", line 673, in _load_unlocked
  File "<frozen importlib._bootstrap_external>", line 658, in exec_module
  File "<frozen importlib._bootstrap_external>", line 764, in get_code
  File "<frozen importlib._bootstrap_external>", line 724, in source_to_code
  File "<frozen importlib._bootstrap>", line 222, in _call_with_frames_removed
  File "/Users/apple/code/python/liuclblog/blog/urls.py", line 17
    TemplateView.†as_view(template_name="blog/register.html"),
                        ^
SyntaxError: invalid character in identifier
[2016-06-16 09:29:47,306] [ERROR] base : Internal Server Error: /
Traceback (most recent call last):
  File "/Users/apple/code/python/virtualsys/blog/lib/python3.5/site-packages/django/core/urlresolvers.py", line 394, in urlconf_module
    return self._urlconf_module
AttributeError: 'RegexURLResolver' object has no attribute '_urlconf_module'

During handling of the above exception, another exception occurred:

Traceback (most recent call last):
  File "/Users/apple/code/python/virtualsys/blog/lib/python3.5/site-packages/django/core/handlers/base.py", line 119, in get_response
    resolver_match = resolver.resolve(request.path_info)
  File "/Users/apple/code/python/virtualsys/blog/lib/python3.5/site-packages/django/core/urlresolvers.py", line 366, in resolve
    for pattern in self.url_patterns:
  File "/Users/apple/code/python/virtualsys/blog/lib/python3.5/site-packages/django/core/urlresolvers.py", line 402, in url_patterns
    patterns = getattr(self.urlconf_module, "urlpatterns", self.urlconf_module)
  File "/Users/apple/code/python/virtualsys/blog/lib/python3.5/site-packages/django/core/urlresolvers.py", line 396, in urlconf_module
    self._urlconf_module = import_module(self.urlconf_name)
  File "/Users/apple/code/python/virtualsys/blog/lib/python3.5/importlib/__init__.py", line 126, in import_module
    return _bootstrap._gcd_import(name[level:], package, level)
  File "<frozen importlib._bootstrap>", line 986, in _gcd_import
  File "<frozen importlib._bootstrap>", line 969, in _find_and_load
  File "<frozen importlib._bootstrap>", line 958, in _find_and_load_unlocked
  File "<frozen importlib._bootstrap>", line 673, in _load_unlocked
  File "<frozen importlib._bootstrap_external>", line 662, in exec_module
  File "<frozen importlib._bootstrap>", line 222, in _call_with_frames_removed
  File "/Users/apple/code/python/liuclblog/liucl_blog/urls.py", line 68, in <module>
    url(r'', include('blog.urls')),
  File "/Users/apple/code/python/virtualsys/blog/lib/python3.5/site-packages/django/conf/urls/__init__.py", line 33, in include
    urlconf_module = import_module(urlconf_module)
  File "/Users/apple/code/python/virtualsys/blog/lib/python3.5/importlib/__init__.py", line 126, in import_module
    return _bootstrap._gcd_import(name[level:], package, level)
  File "<frozen importlib._bootstrap>", line 986, in _gcd_import
  File "<frozen importlib._bootstrap>", line 969, in _find_and_load
  File "<frozen importlib._bootstrap>", line 958, in _find_and_load_unlocked
  File "<frozen importlib._bootstrap>", line 673, in _load_unlocked
  File "<frozen importlib._bootstrap_external>", line 658, in exec_module
  File "<frozen importlib._bootstrap_external>", line 764, in get_code
  File "<frozen importlib._bootstrap_external>", line 724, in source_to_code
  File "<frozen importlib._bootstrap>", line 222, in _call_with_frames_removed
  File "/Users/apple/code/python/liuclblog/blog/urls.py", line 17
    TemplateView.†as_view(template_name="blog/register.html"),
                        ^
SyntaxError: invalid character in identifier
[2016-06-16 09:29:47,826] [ERROR] base : Internal Server Error: /favicon.ico
Traceback (most recent call last):
  File "/Users/apple/code/python/virtualsys/blog/lib/python3.5/site-packages/django/core/urlresolvers.py", line 394, in urlconf_module
    return self._urlconf_module
AttributeError: 'RegexURLResolver' object has no attribute '_urlconf_module'

During handling of the above exception, another exception occurred:

Traceback (most recent call last):
  File "/Users/apple/code/python/virtualsys/blog/lib/python3.5/site-packages/django/core/handlers/base.py", line 108, in get_response
    response = middleware_method(request)
  File "/Users/apple/code/python/virtualsys/blog/lib/python3.5/site-packages/django/middleware/common.py", line 74, in process_request
    if (not urlresolvers.is_valid_path(request.path_info, urlconf) and
  File "/Users/apple/code/python/virtualsys/blog/lib/python3.5/site-packages/django/core/urlresolvers.py", line 647, in is_valid_path
    resolve(path, urlconf)
  File "/Users/apple/code/python/virtualsys/blog/lib/python3.5/site-packages/django/core/urlresolvers.py", line 522, in resolve
    return get_resolver(urlconf).resolve(path)
  File "/Users/apple/code/python/virtualsys/blog/lib/python3.5/site-packages/django/core/urlresolvers.py", line 366, in resolve
    for pattern in self.url_patterns:
  File "/Users/apple/code/python/virtualsys/blog/lib/python3.5/site-packages/django/core/urlresolvers.py", line 402, in url_patterns
    patterns = getattr(self.urlconf_module, "urlpatterns", self.urlconf_module)
  File "/Users/apple/code/python/virtualsys/blog/lib/python3.5/site-packages/django/core/urlresolvers.py", line 396, in urlconf_module
    self._urlconf_module = import_module(self.urlconf_name)
  File "/Users/apple/code/python/virtualsys/blog/lib/python3.5/importlib/__init__.py", line 126, in import_module
    return _bootstrap._gcd_import(name[level:], package, level)
  File "<frozen importlib._bootstrap>", line 986, in _gcd_import
  File "<frozen importlib._bootstrap>", line 969, in _find_and_load
  File "<frozen importlib._bootstrap>", line 958, in _find_and_load_unlocked
  File "<frozen importlib._bootstrap>", line 673, in _load_unlocked
  File "<frozen importlib._bootstrap_external>", line 662, in exec_module
  File "<frozen importlib._bootstrap>", line 222, in _call_with_frames_removed
  File "/Users/apple/code/python/liuclblog/liucl_blog/urls.py", line 68, in <module>
    url(r'', include('blog.urls')),
  File "/Users/apple/code/python/virtualsys/blog/lib/python3.5/site-packages/django/conf/urls/__init__.py", line 33, in include
    urlconf_module = import_module(urlconf_module)
  File "/Users/apple/code/python/virtualsys/blog/lib/python3.5/importlib/__init__.py", line 126, in import_module
    return _bootstrap._gcd_import(name[level:], package, level)
  File "<frozen importlib._bootstrap>", line 986, in _gcd_import
  File "<frozen importlib._bootstrap>", line 969, in _find_and_load
  File "<frozen importlib._bootstrap>", line 958, in _find_and_load_unlocked
  File "<frozen importlib._bootstrap>", line 673, in _load_unlocked
  File "<frozen importlib._bootstrap_external>", line 658, in exec_module
  File "<frozen importlib._bootstrap_external>", line 764, in get_code
  File "<frozen importlib._bootstrap_external>", line 724, in source_to_code
  File "<frozen importlib._bootstrap>", line 222, in _call_with_frames_removed
  File "/Users/apple/code/python/liuclblog/blog/urls.py", line 17
    TemplateView.†as_view(template_name="blog/register.html"),
                        ^
SyntaxError: invalid character in identifier
[2016-06-16 09:29:47,826] [ERROR] base : Internal Server Error: /favicon.ico
Traceback (most recent call last):
  File "/Users/apple/code/python/virtualsys/blog/lib/python3.5/site-packages/django/core/urlresolvers.py", line 394, in urlconf_module
    return self._urlconf_module
AttributeError: 'RegexURLResolver' object has no attribute '_urlconf_module'

During handling of the above exception, another exception occurred:

Traceback (most recent call last):
  File "/Users/apple/code/python/virtualsys/blog/lib/python3.5/site-packages/django/core/handlers/base.py", line 108, in get_response
    response = middleware_method(request)
  File "/Users/apple/code/python/virtualsys/blog/lib/python3.5/site-packages/django/middleware/common.py", line 74, in process_request
    if (not urlresolvers.is_valid_path(request.path_info, urlconf) and
  File "/Users/apple/code/python/virtualsys/blog/lib/python3.5/site-packages/django/core/urlresolvers.py", line 647, in is_valid_path
    resolve(path, urlconf)
  File "/Users/apple/code/python/virtualsys/blog/lib/python3.5/site-packages/django/core/urlresolvers.py", line 522, in resolve
    return get_resolver(urlconf).resolve(path)
  File "/Users/apple/code/python/virtualsys/blog/lib/python3.5/site-packages/django/core/urlresolvers.py", line 366, in resolve
    for pattern in self.url_patterns:
  File "/Users/apple/code/python/virtualsys/blog/lib/python3.5/site-packages/django/core/urlresolvers.py", line 402, in url_patterns
    patterns = getattr(self.urlconf_module, "urlpatterns", self.urlconf_module)
  File "/Users/apple/code/python/virtualsys/blog/lib/python3.5/site-packages/django/core/urlresolvers.py", line 396, in urlconf_module
    self._urlconf_module = import_module(self.urlconf_name)
  File "/Users/apple/code/python/virtualsys/blog/lib/python3.5/importlib/__init__.py", line 126, in import_module
    return _bootstrap._gcd_import(name[level:], package, level)
  File "<frozen importlib._bootstrap>", line 986, in _gcd_import
  File "<frozen importlib._bootstrap>", line 969, in _find_and_load
  File "<frozen importlib._bootstrap>", line 958, in _find_and_load_unlocked
  File "<frozen importlib._bootstrap>", line 673, in _load_unlocked
  File "<frozen importlib._bootstrap_external>", line 662, in exec_module
  File "<frozen importlib._bootstrap>", line 222, in _call_with_frames_removed
  File "/Users/apple/code/python/liuclblog/liucl_blog/urls.py", line 68, in <module>
    url(r'', include('blog.urls')),
  File "/Users/apple/code/python/virtualsys/blog/lib/python3.5/site-packages/django/conf/urls/__init__.py", line 33, in include
    urlconf_module = import_module(urlconf_module)
  File "/Users/apple/code/python/virtualsys/blog/lib/python3.5/importlib/__init__.py", line 126, in import_module
    return _bootstrap._gcd_import(name[level:], package, level)
  File "<frozen importlib._bootstrap>", line 986, in _gcd_import
  File "<frozen importlib._bootstrap>", line 969, in _find_and_load
  File "<frozen importlib._bootstrap>", line 958, in _find_and_load_unlocked
  File "<frozen importlib._bootstrap>", line 673, in _load_unlocked
  File "<frozen importlib._bootstrap_external>", line 658, in exec_module
  File "<frozen importlib._bootstrap_external>", line 764, in get_code
  File "<frozen importlib._bootstrap_external>", line 724, in source_to_code
  File "<frozen importlib._bootstrap>", line 222, in _call_with_frames_removed
  File "/Users/apple/code/python/liuclblog/blog/urls.py", line 17
    TemplateView.†as_view(template_name="blog/register.html"),
                        ^
SyntaxError: invalid character in identifier
[2016-06-16 09:53:19,904] [ERROR] base : Internal Server Error: /article/Package.html
Traceback (most recent call last):
  File "/Users/apple/code/python/virtualsys/blog/lib/python3.5/site-packages/django/core/urlresolvers.py", line 394, in urlconf_module
    return self._urlconf_module
AttributeError: 'RegexURLResolver' object has no attribute '_urlconf_module'

During handling of the above exception, another exception occurred:

Traceback (most recent call last):
  File "/Users/apple/code/python/virtualsys/blog/lib/python3.5/site-packages/django/core/cache/__init__.py", line 84, in _create_cache
    backend_cls = import_string(backend)
  File "/Users/apple/code/python/virtualsys/blog/lib/python3.5/site-packages/django/utils/module_loading.py", line 26, in import_string
    module = import_module(module_path)
  File "/Users/apple/code/python/virtualsys/blog/lib/python3.5/importlib/__init__.py", line 126, in import_module
    return _bootstrap._gcd_import(name[level:], package, level)
  File "<frozen importlib._bootstrap>", line 986, in _gcd_import
  File "<frozen importlib._bootstrap>", line 969, in _find_and_load
  File "<frozen importlib._bootstrap>", line 944, in _find_and_load_unlocked
  File "<frozen importlib._bootstrap>", line 222, in _call_with_frames_removed
  File "<frozen importlib._bootstrap>", line 986, in _gcd_import
  File "<frozen importlib._bootstrap>", line 969, in _find_and_load
  File "<frozen importlib._bootstrap>", line 956, in _find_and_load_unlocked
ImportError: No module named 'redis_cache'

During handling of the above exception, another exception occurred:

Traceback (most recent call last):
  File "/Users/apple/code/python/virtualsys/blog/lib/python3.5/site-packages/django/core/handlers/base.py", line 108, in get_response
    response = middleware_method(request)
  File "/Users/apple/code/python/virtualsys/blog/lib/python3.5/site-packages/django/middleware/common.py", line 74, in process_request
    if (not urlresolvers.is_valid_path(request.path_info, urlconf) and
  File "/Users/apple/code/python/virtualsys/blog/lib/python3.5/site-packages/django/core/urlresolvers.py", line 647, in is_valid_path
    resolve(path, urlconf)
  File "/Users/apple/code/python/virtualsys/blog/lib/python3.5/site-packages/django/core/urlresolvers.py", line 522, in resolve
    return get_resolver(urlconf).resolve(path)
  File "/Users/apple/code/python/virtualsys/blog/lib/python3.5/site-packages/django/core/urlresolvers.py", line 366, in resolve
    for pattern in self.url_patterns:
  File "/Users/apple/code/python/virtualsys/blog/lib/python3.5/site-packages/django/core/urlresolvers.py", line 402, in url_patterns
    patterns = getattr(self.urlconf_module, "urlpatterns", self.urlconf_module)
  File "/Users/apple/code/python/virtualsys/blog/lib/python3.5/site-packages/django/core/urlresolvers.py", line 396, in urlconf_module
    self._urlconf_module = import_module(self.urlconf_name)
  File "/Users/apple/code/python/virtualsys/blog/lib/python3.5/importlib/__init__.py", line 126, in import_module
    return _bootstrap._gcd_import(name[level:], package, level)
  File "<frozen importlib._bootstrap>", line 986, in _gcd_import
  File "<frozen importlib._bootstrap>", line 969, in _find_and_load
  File "<frozen importlib._bootstrap>", line 958, in _find_and_load_unlocked
  File "<frozen importlib._bootstrap>", line 673, in _load_unlocked
  File "<frozen importlib._bootstrap_external>", line 662, in exec_module
  File "<frozen importlib._bootstrap>", line 222, in _call_with_frames_removed
  File "/Users/apple/code/python/liuclblog/liucl_blog/urls.py", line 68, in <module>
    url(r'', include('blog.urls')),
  File "/Users/apple/code/python/virtualsys/blog/lib/python3.5/site-packages/django/conf/urls/__init__.py", line 33, in include
    urlconf_module = import_module(urlconf_module)
  File "/Users/apple/code/python/virtualsys/blog/lib/python3.5/importlib/__init__.py", line 126, in import_module
    return _bootstrap._gcd_import(name[level:], package, level)
  File "<frozen importlib._bootstrap>", line 986, in _gcd_import
  File "<frozen importlib._bootstrap>", line 969, in _find_and_load
  File "<frozen importlib._bootstrap>", line 958, in _find_and_load_unlocked
  File "<frozen importlib._bootstrap>", line 673, in _load_unlocked
  File "<frozen importlib._bootstrap_external>", line 662, in exec_module
  File "<frozen importlib._bootstrap>", line 222, in _call_with_frames_removed
  File "/Users/apple/code/python/liuclblog/blog/urls.py", line 2, in <module>
    from blog.views import (IndexView, ArticleView, AllView, SearchView,
  File "/Users/apple/code/python/liuclblog/blog/views.py", line 26, in <module>
    cache = caches['redis']
  File "/Users/apple/code/python/virtualsys/blog/lib/python3.5/site-packages/django/core/cache/__init__.py", line 113, in __getitem__
    cache = _create_cache(alias)
  File "/Users/apple/code/python/virtualsys/blog/lib/python3.5/site-packages/django/core/cache/__init__.py", line 87, in _create_cache
    "Could not find backend '%s': %s" % (backend, e))
django.core.cache.backends.base.InvalidCacheBackendError: Could not find backend 'redis_cache.cache.RedisCache': No module named 'redis_cache'
[2016-06-16 09:53:19,904] [ERROR] base : Internal Server Error: /article/Package.html
Traceback (most recent call last):
  File "/Users/apple/code/python/virtualsys/blog/lib/python3.5/site-packages/django/core/urlresolvers.py", line 394, in urlconf_module
    return self._urlconf_module
AttributeError: 'RegexURLResolver' object has no attribute '_urlconf_module'

During handling of the above exception, another exception occurred:

Traceback (most recent call last):
  File "/Users/apple/code/python/virtualsys/blog/lib/python3.5/site-packages/django/core/cache/__init__.py", line 84, in _create_cache
    backend_cls = import_string(backend)
  File "/Users/apple/code/python/virtualsys/blog/lib/python3.5/site-packages/django/utils/module_loading.py", line 26, in import_string
    module = import_module(module_path)
  File "/Users/apple/code/python/virtualsys/blog/lib/python3.5/importlib/__init__.py", line 126, in import_module
    return _bootstrap._gcd_import(name[level:], package, level)
  File "<frozen importlib._bootstrap>", line 986, in _gcd_import
  File "<frozen importlib._bootstrap>", line 969, in _find_and_load
  File "<frozen importlib._bootstrap>", line 944, in _find_and_load_unlocked
  File "<frozen importlib._bootstrap>", line 222, in _call_with_frames_removed
  File "<frozen importlib._bootstrap>", line 986, in _gcd_import
  File "<frozen importlib._bootstrap>", line 969, in _find_and_load
  File "<frozen importlib._bootstrap>", line 956, in _find_and_load_unlocked
ImportError: No module named 'redis_cache'

During handling of the above exception, another exception occurred:

Traceback (most recent call last):
  File "/Users/apple/code/python/virtualsys/blog/lib/python3.5/site-packages/django/core/handlers/base.py", line 108, in get_response
    response = middleware_method(request)
  File "/Users/apple/code/python/virtualsys/blog/lib/python3.5/site-packages/django/middleware/common.py", line 74, in process_request
    if (not urlresolvers.is_valid_path(request.path_info, urlconf) and
  File "/Users/apple/code/python/virtualsys/blog/lib/python3.5/site-packages/django/core/urlresolvers.py", line 647, in is_valid_path
    resolve(path, urlconf)
  File "/Users/apple/code/python/virtualsys/blog/lib/python3.5/site-packages/django/core/urlresolvers.py", line 522, in resolve
    return get_resolver(urlconf).resolve(path)
  File "/Users/apple/code/python/virtualsys/blog/lib/python3.5/site-packages/django/core/urlresolvers.py", line 366, in resolve
    for pattern in self.url_patterns:
  File "/Users/apple/code/python/virtualsys/blog/lib/python3.5/site-packages/django/core/urlresolvers.py", line 402, in url_patterns
    patterns = getattr(self.urlconf_module, "urlpatterns", self.urlconf_module)
  File "/Users/apple/code/python/virtualsys/blog/lib/python3.5/site-packages/django/core/urlresolvers.py", line 396, in urlconf_module
    self._urlconf_module = import_module(self.urlconf_name)
  File "/Users/apple/code/python/virtualsys/blog/lib/python3.5/importlib/__init__.py", line 126, in import_module
    return _bootstrap._gcd_import(name[level:], package, level)
  File "<frozen importlib._bootstrap>", line 986, in _gcd_import
  File "<frozen importlib._bootstrap>", line 969, in _find_and_load
  File "<frozen importlib._bootstrap>", line 958, in _find_and_load_unlocked
  File "<frozen importlib._bootstrap>", line 673, in _load_unlocked
  File "<frozen importlib._bootstrap_external>", line 662, in exec_module
  File "<frozen importlib._bootstrap>", line 222, in _call_with_frames_removed
  File "/Users/apple/code/python/liuclblog/liucl_blog/urls.py", line 68, in <module>
    url(r'', include('blog.urls')),
  File "/Users/apple/code/python/virtualsys/blog/lib/python3.5/site-packages/django/conf/urls/__init__.py", line 33, in include
    urlconf_module = import_module(urlconf_module)
  File "/Users/apple/code/python/virtualsys/blog/lib/python3.5/importlib/__init__.py", line 126, in import_module
    return _bootstrap._gcd_import(name[level:], package, level)
  File "<frozen importlib._bootstrap>", line 986, in _gcd_import
  File "<frozen importlib._bootstrap>", line 969, in _find_and_load
  File "<frozen importlib._bootstrap>", line 958, in _find_and_load_unlocked
  File "<frozen importlib._bootstrap>", line 673, in _load_unlocked
  File "<frozen importlib._bootstrap_external>", line 662, in exec_module
  File "<frozen importlib._bootstrap>", line 222, in _call_with_frames_removed
  File "/Users/apple/code/python/liuclblog/blog/urls.py", line 2, in <module>
    from blog.views import (IndexView, ArticleView, AllView, SearchView,
  File "/Users/apple/code/python/liuclblog/blog/views.py", line 26, in <module>
    cache = caches['redis']
  File "/Users/apple/code/python/virtualsys/blog/lib/python3.5/site-packages/django/core/cache/__init__.py", line 113, in __getitem__
    cache = _create_cache(alias)
  File "/Users/apple/code/python/virtualsys/blog/lib/python3.5/site-packages/django/core/cache/__init__.py", line 87, in _create_cache
    "Could not find backend '%s': %s" % (backend, e))
django.core.cache.backends.base.InvalidCacheBackendError: Could not find backend 'redis_cache.cache.RedisCache': No module named 'redis_cache'
[2016-06-16 10:06:50,339] [ERROR] base : Internal Server Error: /article/Package.html
Traceback (most recent call last):
  File "/Users/apple/code/python/virtualsys/blog/lib/python3.5/site-packages/django/core/urlresolvers.py", line 394, in urlconf_module
    return self._urlconf_module
AttributeError: 'RegexURLResolver' object has no attribute '_urlconf_module'

During handling of the above exception, another exception occurred:

Traceback (most recent call last):
  File "/Users/apple/code/python/virtualsys/blog/lib/python3.5/site-packages/django/core/cache/__init__.py", line 84, in _create_cache
    backend_cls = import_string(backend)
  File "/Users/apple/code/python/virtualsys/blog/lib/python3.5/site-packages/django/utils/module_loading.py", line 26, in import_string
    module = import_module(module_path)
  File "/Users/apple/code/python/virtualsys/blog/lib/python3.5/importlib/__init__.py", line 126, in import_module
    return _bootstrap._gcd_import(name[level:], package, level)
  File "<frozen importlib._bootstrap>", line 986, in _gcd_import
  File "<frozen importlib._bootstrap>", line 969, in _find_and_load
  File "<frozen importlib._bootstrap>", line 956, in _find_and_load_unlocked
ImportError: No module named 'redis.cache'

During handling of the above exception, another exception occurred:

Traceback (most recent call last):
  File "/Users/apple/code/python/virtualsys/blog/lib/python3.5/site-packages/django/core/handlers/base.py", line 108, in get_response
    response = middleware_method(request)
  File "/Users/apple/code/python/virtualsys/blog/lib/python3.5/site-packages/django/middleware/common.py", line 74, in process_request
    if (not urlresolvers.is_valid_path(request.path_info, urlconf) and
  File "/Users/apple/code/python/virtualsys/blog/lib/python3.5/site-packages/django/core/urlresolvers.py", line 647, in is_valid_path
    resolve(path, urlconf)
  File "/Users/apple/code/python/virtualsys/blog/lib/python3.5/site-packages/django/core/urlresolvers.py", line 522, in resolve
    return get_resolver(urlconf).resolve(path)
  File "/Users/apple/code/python/virtualsys/blog/lib/python3.5/site-packages/django/core/urlresolvers.py", line 366, in resolve
    for pattern in self.url_patterns:
  File "/Users/apple/code/python/virtualsys/blog/lib/python3.5/site-packages/django/core/urlresolvers.py", line 402, in url_patterns
    patterns = getattr(self.urlconf_module, "urlpatterns", self.urlconf_module)
  File "/Users/apple/code/python/virtualsys/blog/lib/python3.5/site-packages/django/core/urlresolvers.py", line 396, in urlconf_module
    self._urlconf_module = import_module(self.urlconf_name)
  File "/Users/apple/code/python/virtualsys/blog/lib/python3.5/importlib/__init__.py", line 126, in import_module
    return _bootstrap._gcd_import(name[level:], package, level)
  File "<frozen importlib._bootstrap>", line 986, in _gcd_import
  File "<frozen importlib._bootstrap>", line 969, in _find_and_load
  File "<frozen importlib._bootstrap>", line 958, in _find_and_load_unlocked
  File "<frozen importlib._bootstrap>", line 673, in _load_unlocked
  File "<frozen importlib._bootstrap_external>", line 662, in exec_module
  File "<frozen importlib._bootstrap>", line 222, in _call_with_frames_removed
  File "/Users/apple/code/python/liuclblog/liucl_blog/urls.py", line 68, in <module>
    url(r'', include('blog.urls')),
  File "/Users/apple/code/python/virtualsys/blog/lib/python3.5/site-packages/django/conf/urls/__init__.py", line 33, in include
    urlconf_module = import_module(urlconf_module)
  File "/Users/apple/code/python/virtualsys/blog/lib/python3.5/importlib/__init__.py", line 126, in import_module
    return _bootstrap._gcd_import(name[level:], package, level)
  File "<frozen importlib._bootstrap>", line 986, in _gcd_import
  File "<frozen importlib._bootstrap>", line 969, in _find_and_load
  File "<frozen importlib._bootstrap>", line 958, in _find_and_load_unlocked
  File "<frozen importlib._bootstrap>", line 673, in _load_unlocked
  File "<frozen importlib._bootstrap_external>", line 662, in exec_module
  File "<frozen importlib._bootstrap>", line 222, in _call_with_frames_removed
  File "/Users/apple/code/python/liuclblog/blog/urls.py", line 2, in <module>
    from blog.views import (IndexView, ArticleView, AllView, SearchView,
  File "/Users/apple/code/python/liuclblog/blog/views.py", line 26, in <module>
    cache = caches['redis']
  File "/Users/apple/code/python/virtualsys/blog/lib/python3.5/site-packages/django/core/cache/__init__.py", line 113, in __getitem__
    cache = _create_cache(alias)
  File "/Users/apple/code/python/virtualsys/blog/lib/python3.5/site-packages/django/core/cache/__init__.py", line 87, in _create_cache
    "Could not find backend '%s': %s" % (backend, e))
django.core.cache.backends.base.InvalidCacheBackendError: Could not find backend 'redis.cache.RedisCache': No module named 'redis.cache'
[2016-06-16 10:06:50,339] [ERROR] base : Internal Server Error: /article/Package.html
Traceback (most recent call last):
  File "/Users/apple/code/python/virtualsys/blog/lib/python3.5/site-packages/django/core/urlresolvers.py", line 394, in urlconf_module
    return self._urlconf_module
AttributeError: 'RegexURLResolver' object has no attribute '_urlconf_module'

During handling of the above exception, another exception occurred:

Traceback (most recent call last):
  File "/Users/apple/code/python/virtualsys/blog/lib/python3.5/site-packages/django/core/cache/__init__.py", line 84, in _create_cache
    backend_cls = import_string(backend)
  File "/Users/apple/code/python/virtualsys/blog/lib/python3.5/site-packages/django/utils/module_loading.py", line 26, in import_string
    module = import_module(module_path)
  File "/Users/apple/code/python/virtualsys/blog/lib/python3.5/importlib/__init__.py", line 126, in import_module
    return _bootstrap._gcd_import(name[level:], package, level)
  File "<frozen importlib._bootstrap>", line 986, in _gcd_import
  File "<frozen importlib._bootstrap>", line 969, in _find_and_load
  File "<frozen importlib._bootstrap>", line 956, in _find_and_load_unlocked
ImportError: No module named 'redis.cache'

During handling of the above exception, another exception occurred:

Traceback (most recent call last):
  File "/Users/apple/code/python/virtualsys/blog/lib/python3.5/site-packages/django/core/handlers/base.py", line 108, in get_response
    response = middleware_method(request)
  File "/Users/apple/code/python/virtualsys/blog/lib/python3.5/site-packages/django/middleware/common.py", line 74, in process_request
    if (not urlresolvers.is_valid_path(request.path_info, urlconf) and
  File "/Users/apple/code/python/virtualsys/blog/lib/python3.5/site-packages/django/core/urlresolvers.py", line 647, in is_valid_path
    resolve(path, urlconf)
  File "/Users/apple/code/python/virtualsys/blog/lib/python3.5/site-packages/django/core/urlresolvers.py", line 522, in resolve
    return get_resolver(urlconf).resolve(path)
  File "/Users/apple/code/python/virtualsys/blog/lib/python3.5/site-packages/django/core/urlresolvers.py", line 366, in resolve
    for pattern in self.url_patterns:
  File "/Users/apple/code/python/virtualsys/blog/lib/python3.5/site-packages/django/core/urlresolvers.py", line 402, in url_patterns
    patterns = getattr(self.urlconf_module, "urlpatterns", self.urlconf_module)
  File "/Users/apple/code/python/virtualsys/blog/lib/python3.5/site-packages/django/core/urlresolvers.py", line 396, in urlconf_module
    self._urlconf_module = import_module(self.urlconf_name)
  File "/Users/apple/code/python/virtualsys/blog/lib/python3.5/importlib/__init__.py", line 126, in import_module
    return _bootstrap._gcd_import(name[level:], package, level)
  File "<frozen importlib._bootstrap>", line 986, in _gcd_import
  File "<frozen importlib._bootstrap>", line 969, in _find_and_load
  File "<frozen importlib._bootstrap>", line 958, in _find_and_load_unlocked
  File "<frozen importlib._bootstrap>", line 673, in _load_unlocked
  File "<frozen importlib._bootstrap_external>", line 662, in exec_module
  File "<frozen importlib._bootstrap>", line 222, in _call_with_frames_removed
  File "/Users/apple/code/python/liuclblog/liucl_blog/urls.py", line 68, in <module>
    url(r'', include('blog.urls')),
  File "/Users/apple/code/python/virtualsys/blog/lib/python3.5/site-packages/django/conf/urls/__init__.py", line 33, in include
    urlconf_module = import_module(urlconf_module)
  File "/Users/apple/code/python/virtualsys/blog/lib/python3.5/importlib/__init__.py", line 126, in import_module
    return _bootstrap._gcd_import(name[level:], package, level)
  File "<frozen importlib._bootstrap>", line 986, in _gcd_import
  File "<frozen importlib._bootstrap>", line 969, in _find_and_load
  File "<frozen importlib._bootstrap>", line 958, in _find_and_load_unlocked
  File "<frozen importlib._bootstrap>", line 673, in _load_unlocked
  File "<frozen importlib._bootstrap_external>", line 662, in exec_module
  File "<frozen importlib._bootstrap>", line 222, in _call_with_frames_removed
  File "/Users/apple/code/python/liuclblog/blog/urls.py", line 2, in <module>
    from blog.views import (IndexView, ArticleView, AllView, SearchView,
  File "/Users/apple/code/python/liuclblog/blog/views.py", line 26, in <module>
    cache = caches['redis']
  File "/Users/apple/code/python/virtualsys/blog/lib/python3.5/site-packages/django/core/cache/__init__.py", line 113, in __getitem__
    cache = _create_cache(alias)
  File "/Users/apple/code/python/virtualsys/blog/lib/python3.5/site-packages/django/core/cache/__init__.py", line 87, in _create_cache
    "Could not find backend '%s': %s" % (backend, e))
django.core.cache.backends.base.InvalidCacheBackendError: Could not find backend 'redis.cache.RedisCache': No module named 'redis.cache'
[2016-06-16 10:06:52,530] [ERROR] base : Internal Server Error: /article/Package.html
Traceback (most recent call last):
  File "/Users/apple/code/python/virtualsys/blog/lib/python3.5/site-packages/django/core/urlresolvers.py", line 394, in urlconf_module
    return self._urlconf_module
AttributeError: 'RegexURLResolver' object has no attribute '_urlconf_module'

During handling of the above exception, another exception occurred:

Traceback (most recent call last):
  File "/Users/apple/code/python/virtualsys/blog/lib/python3.5/site-packages/django/core/cache/__init__.py", line 84, in _create_cache
    backend_cls = import_string(backend)
  File "/Users/apple/code/python/virtualsys/blog/lib/python3.5/site-packages/django/utils/module_loading.py", line 26, in import_string
    module = import_module(module_path)
  File "/Users/apple/code/python/virtualsys/blog/lib/python3.5/importlib/__init__.py", line 126, in import_module
    return _bootstrap._gcd_import(name[level:], package, level)
  File "<frozen importlib._bootstrap>", line 986, in _gcd_import
  File "<frozen importlib._bootstrap>", line 969, in _find_and_load
  File "<frozen importlib._bootstrap>", line 956, in _find_and_load_unlocked
ImportError: No module named 'redis.cache'

During handling of the above exception, another exception occurred:

Traceback (most recent call last):
  File "/Users/apple/code/python/virtualsys/blog/lib/python3.5/site-packages/django/core/handlers/base.py", line 108, in get_response
    response = middleware_method(request)
  File "/Users/apple/code/python/virtualsys/blog/lib/python3.5/site-packages/django/middleware/common.py", line 74, in process_request
    if (not urlresolvers.is_valid_path(request.path_info, urlconf) and
  File "/Users/apple/code/python/virtualsys/blog/lib/python3.5/site-packages/django/core/urlresolvers.py", line 647, in is_valid_path
    resolve(path, urlconf)
  File "/Users/apple/code/python/virtualsys/blog/lib/python3.5/site-packages/django/core/urlresolvers.py", line 522, in resolve
    return get_resolver(urlconf).resolve(path)
  File "/Users/apple/code/python/virtualsys/blog/lib/python3.5/site-packages/django/core/urlresolvers.py", line 366, in resolve
    for pattern in self.url_patterns:
  File "/Users/apple/code/python/virtualsys/blog/lib/python3.5/site-packages/django/core/urlresolvers.py", line 402, in url_patterns
    patterns = getattr(self.urlconf_module, "urlpatterns", self.urlconf_module)
  File "/Users/apple/code/python/virtualsys/blog/lib/python3.5/site-packages/django/core/urlresolvers.py", line 396, in urlconf_module
    self._urlconf_module = import_module(self.urlconf_name)
  File "/Users/apple/code/python/virtualsys/blog/lib/python3.5/importlib/__init__.py", line 126, in import_module
    return _bootstrap._gcd_import(name[level:], package, level)
  File "<frozen importlib._bootstrap>", line 986, in _gcd_import
  File "<frozen importlib._bootstrap>", line 969, in _find_and_load
  File "<frozen importlib._bootstrap>", line 958, in _find_and_load_unlocked
  File "<frozen importlib._bootstrap>", line 673, in _load_unlocked
  File "<frozen importlib._bootstrap_external>", line 662, in exec_module
  File "<frozen importlib._bootstrap>", line 222, in _call_with_frames_removed
  File "/Users/apple/code/python/liuclblog/liucl_blog/urls.py", line 68, in <module>
    url(r'', include('blog.urls')),
  File "/Users/apple/code/python/virtualsys/blog/lib/python3.5/site-packages/django/conf/urls/__init__.py", line 33, in include
    urlconf_module = import_module(urlconf_module)
  File "/Users/apple/code/python/virtualsys/blog/lib/python3.5/importlib/__init__.py", line 126, in import_module
    return _bootstrap._gcd_import(name[level:], package, level)
  File "<frozen importlib._bootstrap>", line 986, in _gcd_import
  File "<frozen importlib._bootstrap>", line 969, in _find_and_load
  File "<frozen importlib._bootstrap>", line 958, in _find_and_load_unlocked
  File "<frozen importlib._bootstrap>", line 673, in _load_unlocked
  File "<frozen importlib._bootstrap_external>", line 662, in exec_module
  File "<frozen importlib._bootstrap>", line 222, in _call_with_frames_removed
  File "/Users/apple/code/python/liuclblog/blog/urls.py", line 2, in <module>
    from blog.views import (IndexView, ArticleView, AllView, SearchView,
  File "/Users/apple/code/python/liuclblog/blog/views.py", line 26, in <module>
    cache = caches['redis']
  File "/Users/apple/code/python/virtualsys/blog/lib/python3.5/site-packages/django/core/cache/__init__.py", line 113, in __getitem__
    cache = _create_cache(alias)
  File "/Users/apple/code/python/virtualsys/blog/lib/python3.5/site-packages/django/core/cache/__init__.py", line 87, in _create_cache
    "Could not find backend '%s': %s" % (backend, e))
django.core.cache.backends.base.InvalidCacheBackendError: Could not find backend 'redis.cache.RedisCache': No module named 'redis.cache'
[2016-06-16 10:06:52,530] [ERROR] base : Internal Server Error: /article/Package.html
Traceback (most recent call last):
  File "/Users/apple/code/python/virtualsys/blog/lib/python3.5/site-packages/django/core/urlresolvers.py", line 394, in urlconf_module
    return self._urlconf_module
AttributeError: 'RegexURLResolver' object has no attribute '_urlconf_module'

During handling of the above exception, another exception occurred:

Traceback (most recent call last):
  File "/Users/apple/code/python/virtualsys/blog/lib/python3.5/site-packages/django/core/cache/__init__.py", line 84, in _create_cache
    backend_cls = import_string(backend)
  File "/Users/apple/code/python/virtualsys/blog/lib/python3.5/site-packages/django/utils/module_loading.py", line 26, in import_string
    module = import_module(module_path)
  File "/Users/apple/code/python/virtualsys/blog/lib/python3.5/importlib/__init__.py", line 126, in import_module
    return _bootstrap._gcd_import(name[level:], package, level)
  File "<frozen importlib._bootstrap>", line 986, in _gcd_import
  File "<frozen importlib._bootstrap>", line 969, in _find_and_load
  File "<frozen importlib._bootstrap>", line 956, in _find_and_load_unlocked
ImportError: No module named 'redis.cache'

During handling of the above exception, another exception occurred:

Traceback (most recent call last):
  File "/Users/apple/code/python/virtualsys/blog/lib/python3.5/site-packages/django/core/handlers/base.py", line 108, in get_response
    response = middleware_method(request)
  File "/Users/apple/code/python/virtualsys/blog/lib/python3.5/site-packages/django/middleware/common.py", line 74, in process_request
    if (not urlresolvers.is_valid_path(request.path_info, urlconf) and
  File "/Users/apple/code/python/virtualsys/blog/lib/python3.5/site-packages/django/core/urlresolvers.py", line 647, in is_valid_path
    resolve(path, urlconf)
  File "/Users/apple/code/python/virtualsys/blog/lib/python3.5/site-packages/django/core/urlresolvers.py", line 522, in resolve
    return get_resolver(urlconf).resolve(path)
  File "/Users/apple/code/python/virtualsys/blog/lib/python3.5/site-packages/django/core/urlresolvers.py", line 366, in resolve
    for pattern in self.url_patterns:
  File "/Users/apple/code/python/virtualsys/blog/lib/python3.5/site-packages/django/core/urlresolvers.py", line 402, in url_patterns
    patterns = getattr(self.urlconf_module, "urlpatterns", self.urlconf_module)
  File "/Users/apple/code/python/virtualsys/blog/lib/python3.5/site-packages/django/core/urlresolvers.py", line 396, in urlconf_module
    self._urlconf_module = import_module(self.urlconf_name)
  File "/Users/apple/code/python/virtualsys/blog/lib/python3.5/importlib/__init__.py", line 126, in import_module
    return _bootstrap._gcd_import(name[level:], package, level)
  File "<frozen importlib._bootstrap>", line 986, in _gcd_import
  File "<frozen importlib._bootstrap>", line 969, in _find_and_load
  File "<frozen importlib._bootstrap>", line 958, in _find_and_load_unlocked
  File "<frozen importlib._bootstrap>", line 673, in _load_unlocked
  File "<frozen importlib._bootstrap_external>", line 662, in exec_module
  File "<frozen importlib._bootstrap>", line 222, in _call_with_frames_removed
  File "/Users/apple/code/python/liuclblog/liucl_blog/urls.py", line 68, in <module>
    url(r'', include('blog.urls')),
  File "/Users/apple/code/python/virtualsys/blog/lib/python3.5/site-packages/django/conf/urls/__init__.py", line 33, in include
    urlconf_module = import_module(urlconf_module)
  File "/Users/apple/code/python/virtualsys/blog/lib/python3.5/importlib/__init__.py", line 126, in import_module
    return _bootstrap._gcd_import(name[level:], package, level)
  File "<frozen importlib._bootstrap>", line 986, in _gcd_import
  File "<frozen importlib._bootstrap>", line 969, in _find_and_load
  File "<frozen importlib._bootstrap>", line 958, in _find_and_load_unlocked
  File "<frozen importlib._bootstrap>", line 673, in _load_unlocked
  File "<frozen importlib._bootstrap_external>", line 662, in exec_module
  File "<frozen importlib._bootstrap>", line 222, in _call_with_frames_removed
  File "/Users/apple/code/python/liuclblog/blog/urls.py", line 2, in <module>
    from blog.views import (IndexView, ArticleView, AllView, SearchView,
  File "/Users/apple/code/python/liuclblog/blog/views.py", line 26, in <module>
    cache = caches['redis']
  File "/Users/apple/code/python/virtualsys/blog/lib/python3.5/site-packages/django/core/cache/__init__.py", line 113, in __getitem__
    cache = _create_cache(alias)
  File "/Users/apple/code/python/virtualsys/blog/lib/python3.5/site-packages/django/core/cache/__init__.py", line 87, in _create_cache
    "Could not find backend '%s': %s" % (backend, e))
django.core.cache.backends.base.InvalidCacheBackendError: Could not find backend 'redis.cache.RedisCache': No module named 'redis.cache'
[2016-06-16 10:11:49,714] [ERROR] base : Internal Server Error: /article/Package.html
Traceback (most recent call last):
  File "/Users/apple/code/python/virtualsys/blog/lib/python3.5/site-packages/django/core/handlers/base.py", line 132, in get_response
    response = wrapped_callback(request, *callback_args, **callback_kwargs)
  File "/Users/apple/code/python/virtualsys/blog/lib/python3.5/site-packages/django/views/generic/base.py", line 71, in view
    return self.dispatch(request, *args, **kwargs)
  File "/Users/apple/code/python/virtualsys/blog/lib/python3.5/site-packages/django/views/generic/base.py", line 89, in dispatch
    return handler(request, *args, **kwargs)
  File "/Users/apple/code/python/liuclblog/blog/views.py", line 113, in get
    return super(ArticleView, self).get(request, *args, **kwargs)
  File "/Users/apple/code/python/virtualsys/blog/lib/python3.5/site-packages/django/views/generic/detail.py", line 115, in get
    self.object = self.get_object()
  File "/Users/apple/code/python/liuclblog/blog/views.py", line 131, in get_object
    print(set['title'])
TypeError: 'Article' object is not subscriptable
[2016-06-16 10:11:49,714] [ERROR] base : Internal Server Error: /article/Package.html
Traceback (most recent call last):
  File "/Users/apple/code/python/virtualsys/blog/lib/python3.5/site-packages/django/core/handlers/base.py", line 132, in get_response
    response = wrapped_callback(request, *callback_args, **callback_kwargs)
  File "/Users/apple/code/python/virtualsys/blog/lib/python3.5/site-packages/django/views/generic/base.py", line 71, in view
    return self.dispatch(request, *args, **kwargs)
  File "/Users/apple/code/python/virtualsys/blog/lib/python3.5/site-packages/django/views/generic/base.py", line 89, in dispatch
    return handler(request, *args, **kwargs)
  File "/Users/apple/code/python/liuclblog/blog/views.py", line 113, in get
    return super(ArticleView, self).get(request, *args, **kwargs)
  File "/Users/apple/code/python/virtualsys/blog/lib/python3.5/site-packages/django/views/generic/detail.py", line 115, in get
    self.object = self.get_object()
  File "/Users/apple/code/python/liuclblog/blog/views.py", line 131, in get_object
    print(set['title'])
TypeError: 'Article' object is not subscriptable
[2016-06-16 10:12:13,035] [ERROR] base : Internal Server Error: /article/Package.html
Traceback (most recent call last):
  File "/Users/apple/code/python/virtualsys/blog/lib/python3.5/site-packages/django/core/handlers/base.py", line 132, in get_response
    response = wrapped_callback(request, *callback_args, **callback_kwargs)
  File "/Users/apple/code/python/virtualsys/blog/lib/python3.5/site-packages/django/views/generic/base.py", line 71, in view
    return self.dispatch(request, *args, **kwargs)
  File "/Users/apple/code/python/virtualsys/blog/lib/python3.5/site-packages/django/views/generic/base.py", line 89, in dispatch
    return handler(request, *args, **kwargs)
  File "/Users/apple/code/python/liuclblog/blog/views.py", line 113, in get
    return super(ArticleView, self).get(request, *args, **kwargs)
  File "/Users/apple/code/python/virtualsys/blog/lib/python3.5/site-packages/django/views/generic/detail.py", line 115, in get
    self.object = self.get_object()
  File "/Users/apple/code/python/liuclblog/blog/views.py", line 131, in get_object
    print(set['Article'])
TypeError: 'Article' object is not subscriptable
[2016-06-16 10:12:13,035] [ERROR] base : Internal Server Error: /article/Package.html
Traceback (most recent call last):
  File "/Users/apple/code/python/virtualsys/blog/lib/python3.5/site-packages/django/core/handlers/base.py", line 132, in get_response
    response = wrapped_callback(request, *callback_args, **callback_kwargs)
  File "/Users/apple/code/python/virtualsys/blog/lib/python3.5/site-packages/django/views/generic/base.py", line 71, in view
    return self.dispatch(request, *args, **kwargs)
  File "/Users/apple/code/python/virtualsys/blog/lib/python3.5/site-packages/django/views/generic/base.py", line 89, in dispatch
    return handler(request, *args, **kwargs)
  File "/Users/apple/code/python/liuclblog/blog/views.py", line 113, in get
    return super(ArticleView, self).get(request, *args, **kwargs)
  File "/Users/apple/code/python/virtualsys/blog/lib/python3.5/site-packages/django/views/generic/detail.py", line 115, in get
    self.object = self.get_object()
  File "/Users/apple/code/python/liuclblog/blog/views.py", line 131, in get_object
    print(set['Article'])
TypeError: 'Article' object is not subscriptable
[2016-06-16 10:23:54,981] [ERROR] base : Internal Server Error: /article/Package.html
Traceback (most recent call last):
  File "/Users/apple/code/python/virtualsys/blog/lib/python3.5/site-packages/django/core/handlers/base.py", line 132, in get_response
    response = wrapped_callback(request, *callback_args, **callback_kwargs)
  File "/Users/apple/code/python/virtualsys/blog/lib/python3.5/site-packages/django/views/generic/base.py", line 71, in view
    return self.dispatch(request, *args, **kwargs)
  File "/Users/apple/code/python/virtualsys/blog/lib/python3.5/site-packages/django/views/generic/base.py", line 89, in dispatch
    return handler(request, *args, **kwargs)
  File "/Users/apple/code/python/liuclblog/blog/views.py", line 113, in get
    return super(ArticleView, self).get(request, *args, **kwargs)
  File "/Users/apple/code/python/virtualsys/blog/lib/python3.5/site-packages/django/views/generic/detail.py", line 115, in get
    self.object = self.get_object()
  File "/Users/apple/code/python/liuclblog/blog/views.py", line 131, in get_object
    if read_from_cache(set.title):
NameError: name 'read_from_cache' is not defined
[2016-06-16 10:23:54,981] [ERROR] base : Internal Server Error: /article/Package.html
Traceback (most recent call last):
  File "/Users/apple/code/python/virtualsys/blog/lib/python3.5/site-packages/django/core/handlers/base.py", line 132, in get_response
    response = wrapped_callback(request, *callback_args, **callback_kwargs)
  File "/Users/apple/code/python/virtualsys/blog/lib/python3.5/site-packages/django/views/generic/base.py", line 71, in view
    return self.dispatch(request, *args, **kwargs)
  File "/Users/apple/code/python/virtualsys/blog/lib/python3.5/site-packages/django/views/generic/base.py", line 89, in dispatch
    return handler(request, *args, **kwargs)
  File "/Users/apple/code/python/liuclblog/blog/views.py", line 113, in get
    return super(ArticleView, self).get(request, *args, **kwargs)
  File "/Users/apple/code/python/virtualsys/blog/lib/python3.5/site-packages/django/views/generic/detail.py", line 115, in get
    self.object = self.get_object()
  File "/Users/apple/code/python/liuclblog/blog/views.py", line 131, in get_object
    if read_from_cache(set.title):
NameError: name 'read_from_cache' is not defined
[2016-06-16 10:24:39,206] [ERROR] base : Internal Server Error: /article/Package.html
Traceback (most recent call last):
  File "/Users/apple/code/python/virtualsys/blog/lib/python3.5/site-packages/django/core/handlers/base.py", line 132, in get_response
    response = wrapped_callback(request, *callback_args, **callback_kwargs)
  File "/Users/apple/code/python/virtualsys/blog/lib/python3.5/site-packages/django/views/generic/base.py", line 71, in view
    return self.dispatch(request, *args, **kwargs)
  File "/Users/apple/code/python/virtualsys/blog/lib/python3.5/site-packages/django/views/generic/base.py", line 89, in dispatch
    return handler(request, *args, **kwargs)
  File "/Users/apple/code/python/liuclblog/blog/views.py", line 113, in get
    return super(ArticleView, self).get(request, *args, **kwargs)
  File "/Users/apple/code/python/virtualsys/blog/lib/python3.5/site-packages/django/views/generic/detail.py", line 115, in get
    self.object = self.get_object()
  File "/Users/apple/code/python/liuclblog/blog/views.py", line 131, in get_object
    if read_from_cache(self, set.title):
NameError: name 'read_from_cache' is not defined
[2016-06-16 10:24:39,206] [ERROR] base : Internal Server Error: /article/Package.html
Traceback (most recent call last):
  File "/Users/apple/code/python/virtualsys/blog/lib/python3.5/site-packages/django/core/handlers/base.py", line 132, in get_response
    response = wrapped_callback(request, *callback_args, **callback_kwargs)
  File "/Users/apple/code/python/virtualsys/blog/lib/python3.5/site-packages/django/views/generic/base.py", line 71, in view
    return self.dispatch(request, *args, **kwargs)
  File "/Users/apple/code/python/virtualsys/blog/lib/python3.5/site-packages/django/views/generic/base.py", line 89, in dispatch
    return handler(request, *args, **kwargs)
  File "/Users/apple/code/python/liuclblog/blog/views.py", line 113, in get
    return super(ArticleView, self).get(request, *args, **kwargs)
  File "/Users/apple/code/python/virtualsys/blog/lib/python3.5/site-packages/django/views/generic/detail.py", line 115, in get
    self.object = self.get_object()
  File "/Users/apple/code/python/liuclblog/blog/views.py", line 131, in get_object
    if read_from_cache(self, set.title):
NameError: name 'read_from_cache' is not defined
[2016-06-25 21:29:05,098] [ERROR] base : Internal Server Error: /testpost
Traceback (most recent call last):
  File "/Users/apple/code/python/virtualsys/blog/lib/python3.5/site-packages/django/core/handlers/base.py", line 151, in get_response
    % (callback.__module__, view_name))
ValueError: The view blog.views.TextPost didn't return an HttpResponse object. It returned None instead.
[2016-06-25 21:29:05,098] [ERROR] base : Internal Server Error: /testpost
Traceback (most recent call last):
  File "/Users/apple/code/python/virtualsys/blog/lib/python3.5/site-packages/django/core/handlers/base.py", line 151, in get_response
    % (callback.__module__, view_name))
ValueError: The view blog.views.TextPost didn't return an HttpResponse object. It returned None instead.
[2016-06-25 21:30:26,441] [ERROR] base : Internal Server Error: /testpost
Traceback (most recent call last):
  File "/Users/apple/code/python/virtualsys/blog/lib/python3.5/site-packages/django/core/handlers/base.py", line 132, in get_response
    response = wrapped_callback(request, *callback_args, **callback_kwargs)
  File "/Users/apple/code/python/liuclblog/blog/views.py", line 82, in TextPost
    return HttpResponse(request[0])
TypeError: 'WSGIRequest' object does not support indexing
[2016-06-25 21:30:26,441] [ERROR] base : Internal Server Error: /testpost
Traceback (most recent call last):
  File "/Users/apple/code/python/virtualsys/blog/lib/python3.5/site-packages/django/core/handlers/base.py", line 132, in get_response
    response = wrapped_callback(request, *callback_args, **callback_kwargs)
  File "/Users/apple/code/python/liuclblog/blog/views.py", line 82, in TextPost
    return HttpResponse(request[0])
TypeError: 'WSGIRequest' object does not support indexing
[2016-06-25 21:31:26,731] [ERROR] base : Internal Server Error: /testpost
Traceback (most recent call last):
  File "/Users/apple/code/python/virtualsys/blog/lib/python3.5/site-packages/django/utils/datastructures.py", line 320, in __getitem__
    list_ = super(MultiValueDict, self).__getitem__(key)
KeyError: 0

During handling of the above exception, another exception occurred:

Traceback (most recent call last):
  File "/Users/apple/code/python/virtualsys/blog/lib/python3.5/site-packages/django/core/handlers/base.py", line 132, in get_response
    response = wrapped_callback(request, *callback_args, **callback_kwargs)
  File "/Users/apple/code/python/liuclblog/blog/views.py", line 82, in TextPost
    return HttpResponse(request.GET[0])
  File "/Users/apple/code/python/virtualsys/blog/lib/python3.5/site-packages/django/utils/datastructures.py", line 322, in __getitem__
    raise MultiValueDictKeyError(repr(key))
django.utils.datastructures.MultiValueDictKeyError: '0'
[2016-06-25 21:31:26,731] [ERROR] base : Internal Server Error: /testpost
Traceback (most recent call last):
  File "/Users/apple/code/python/virtualsys/blog/lib/python3.5/site-packages/django/utils/datastructures.py", line 320, in __getitem__
    list_ = super(MultiValueDict, self).__getitem__(key)
KeyError: 0

During handling of the above exception, another exception occurred:

Traceback (most recent call last):
  File "/Users/apple/code/python/virtualsys/blog/lib/python3.5/site-packages/django/core/handlers/base.py", line 132, in get_response
    response = wrapped_callback(request, *callback_args, **callback_kwargs)
  File "/Users/apple/code/python/liuclblog/blog/views.py", line 82, in TextPost
    return HttpResponse(request.GET[0])
  File "/Users/apple/code/python/virtualsys/blog/lib/python3.5/site-packages/django/utils/datastructures.py", line 322, in __getitem__
    raise MultiValueDictKeyError(repr(key))
django.utils.datastructures.MultiValueDictKeyError: '0'
[2016-06-25 21:31:33,415] [ERROR] base : Internal Server Error: /testpost
Traceback (most recent call last):
  File "/Users/apple/code/python/virtualsys/blog/lib/python3.5/site-packages/django/utils/datastructures.py", line 320, in __getitem__
    list_ = super(MultiValueDict, self).__getitem__(key)
KeyError: 0

During handling of the above exception, another exception occurred:

Traceback (most recent call last):
  File "/Users/apple/code/python/virtualsys/blog/lib/python3.5/site-packages/django/core/handlers/base.py", line 132, in get_response
    response = wrapped_callback(request, *callback_args, **callback_kwargs)
  File "/Users/apple/code/python/liuclblog/blog/views.py", line 82, in TextPost
    return HttpResponse(request.GET[0])
  File "/Users/apple/code/python/virtualsys/blog/lib/python3.5/site-packages/django/utils/datastructures.py", line 322, in __getitem__
    raise MultiValueDictKeyError(repr(key))
django.utils.datastructures.MultiValueDictKeyError: '0'
[2016-06-25 21:31:33,415] [ERROR] base : Internal Server Error: /testpost
Traceback (most recent call last):
  File "/Users/apple/code/python/virtualsys/blog/lib/python3.5/site-packages/django/utils/datastructures.py", line 320, in __getitem__
    list_ = super(MultiValueDict, self).__getitem__(key)
KeyError: 0

During handling of the above exception, another exception occurred:

Traceback (most recent call last):
  File "/Users/apple/code/python/virtualsys/blog/lib/python3.5/site-packages/django/core/handlers/base.py", line 132, in get_response
    response = wrapped_callback(request, *callback_args, **callback_kwargs)
  File "/Users/apple/code/python/liuclblog/blog/views.py", line 82, in TextPost
    return HttpResponse(request.GET[0])
  File "/Users/apple/code/python/virtualsys/blog/lib/python3.5/site-packages/django/utils/datastructures.py", line 322, in __getitem__
    raise MultiValueDictKeyError(repr(key))
django.utils.datastructures.MultiValueDictKeyError: '0'
[2016-06-25 23:15:25,359] [ERROR] views : [BaseMixin]加载基本信息出错
[2016-06-25 23:15:25,423] [ERROR] base : Internal Server Error: /
Traceback (most recent call last):
  File "/Users/apple/code/python/virtualsys/blog/lib/python3.5/site-packages/django/db/backends/utils.py", line 64, in execute
    return self.cursor.execute(sql, params)
  File "/Users/apple/code/python/virtualsys/blog/lib/python3.5/site-packages/django/db/backends/sqlite3/base.py", line 318, in execute
    return Database.Cursor.execute(self, query, params)
sqlite3.OperationalError: no such table: liucl_comments_comment

The above exception was the direct cause of the following exception:

Traceback (most recent call last):
  File "/Users/apple/code/python/virtualsys/blog/lib/python3.5/site-packages/django/core/handlers/base.py", line 164, in get_response
    response = response.render()
  File "/Users/apple/code/python/virtualsys/blog/lib/python3.5/site-packages/django/template/response.py", line 158, in render
    self.content = self.rendered_content
  File "/Users/apple/code/python/virtualsys/blog/lib/python3.5/site-packages/django/template/response.py", line 135, in rendered_content
    content = template.render(context, self._request)
  File "/Users/apple/code/python/virtualsys/blog/lib/python3.5/site-packages/django/template/backends/django.py", line 74, in render
    return self.template.render(context)
  File "/Users/apple/code/python/virtualsys/blog/lib/python3.5/site-packages/django/template/base.py", line 209, in render
    return self._render(context)
  File "/Users/apple/code/python/virtualsys/blog/lib/python3.5/site-packages/django/template/base.py", line 201, in _render
    return self.nodelist.render(context)
  File "/Users/apple/code/python/virtualsys/blog/lib/python3.5/site-packages/django/template/base.py", line 903, in render
    bit = self.render_node(node, context)
  File "/Users/apple/code/python/virtualsys/blog/lib/python3.5/site-packages/django/template/debug.py", line 79, in render_node
    return node.render(context)
  File "/Users/apple/code/python/virtualsys/blog/lib/python3.5/site-packages/django/template/loader_tags.py", line 135, in render
    return compiled_parent._render(context)
  File "/Users/apple/code/python/virtualsys/blog/lib/python3.5/site-packages/django/template/base.py", line 201, in _render
    return self.nodelist.render(context)
  File "/Users/apple/code/python/virtualsys/blog/lib/python3.5/site-packages/django/template/base.py", line 903, in render
    bit = self.render_node(node, context)
  File "/Users/apple/code/python/virtualsys/blog/lib/python3.5/site-packages/django/template/debug.py", line 79, in render_node
    return node.render(context)
  File "/Users/apple/code/python/virtualsys/blog/lib/python3.5/site-packages/django/template/loader_tags.py", line 65, in render
    result = block.nodelist.render(context)
  File "/Users/apple/code/python/virtualsys/blog/lib/python3.5/site-packages/django/template/base.py", line 903, in render
    bit = self.render_node(node, context)
  File "/Users/apple/code/python/virtualsys/blog/lib/python3.5/site-packages/django/template/debug.py", line 79, in render_node
    return node.render(context)
  File "/Users/apple/code/python/virtualsys/blog/lib/python3.5/site-packages/django/template/defaulttags.py", line 329, in render
    return nodelist.render(context)
  File "/Users/apple/code/python/virtualsys/blog/lib/python3.5/site-packages/django/template/base.py", line 903, in render
    bit = self.render_node(node, context)
  File "/Users/apple/code/python/virtualsys/blog/lib/python3.5/site-packages/django/template/debug.py", line 79, in render_node
    return node.render(context)
  File "/Users/apple/code/python/virtualsys/blog/lib/python3.5/site-packages/django/template/defaulttags.py", line 576, in render
    return self.nodelist.render(context)
  File "/Users/apple/code/python/virtualsys/blog/lib/python3.5/site-packages/django/template/base.py", line 903, in render
    bit = self.render_node(node, context)
  File "/Users/apple/code/python/virtualsys/blog/lib/python3.5/site-packages/django/template/debug.py", line 79, in render_node
    return node.render(context)
  File "/Users/apple/code/python/virtualsys/blog/lib/python3.5/site-packages/django/template/defaulttags.py", line 217, in render
    nodelist.append(node.render(context))
  File "/Users/apple/code/python/virtualsys/blog/lib/python3.5/site-packages/django/template/loader_tags.py", line 159, in render
    return template.render(context)
  File "/Users/apple/code/python/virtualsys/blog/lib/python3.5/site-packages/django/template/base.py", line 211, in render
    return self._render(context)
  File "/Users/apple/code/python/virtualsys/blog/lib/python3.5/site-packages/django/template/base.py", line 201, in _render
    return self.nodelist.render(context)
  File "/Users/apple/code/python/virtualsys/blog/lib/python3.5/site-packages/django/template/base.py", line 903, in render
    bit = self.render_node(node, context)
  File "/Users/apple/code/python/virtualsys/blog/lib/python3.5/site-packages/django/template/debug.py", line 79, in render_node
    return node.render(context)
  File "/Users/apple/code/python/virtualsys/blog/lib/python3.5/site-packages/django/template/debug.py", line 89, in render
    output = self.filter_expression.resolve(context)
  File "/Users/apple/code/python/virtualsys/blog/lib/python3.5/site-packages/django/template/base.py", line 674, in resolve
    new_obj = func(obj, *arg_vals)
  File "/Users/apple/code/python/virtualsys/blog/lib/python3.5/site-packages/django/template/defaultfilters.py", line 582, in length
    return len(value)
  File "/Users/apple/code/python/virtualsys/blog/lib/python3.5/site-packages/django/db/models/query.py", line 144, in __len__
    self._fetch_all()
  File "/Users/apple/code/python/virtualsys/blog/lib/python3.5/site-packages/django/db/models/query.py", line 965, in _fetch_all
    self._result_cache = list(self.iterator())
  File "/Users/apple/code/python/virtualsys/blog/lib/python3.5/site-packages/django/db/models/query.py", line 238, in iterator
    results = compiler.execute_sql()
  File "/Users/apple/code/python/virtualsys/blog/lib/python3.5/site-packages/django/db/models/sql/compiler.py", line 829, in execute_sql
    cursor.execute(sql, params)
  File "/Users/apple/code/python/virtualsys/blog/lib/python3.5/site-packages/django/db/backends/utils.py", line 79, in execute
    return super(CursorDebugWrapper, self).execute(sql, params)
  File "/Users/apple/code/python/virtualsys/blog/lib/python3.5/site-packages/django/db/backends/utils.py", line 64, in execute
    return self.cursor.execute(sql, params)
  File "/Users/apple/code/python/virtualsys/blog/lib/python3.5/site-packages/django/db/utils.py", line 97, in __exit__
    six.reraise(dj_exc_type, dj_exc_value, traceback)
  File "/Users/apple/code/python/virtualsys/blog/lib/python3.5/site-packages/django/utils/six.py", line 658, in reraise
    raise value.with_traceback(tb)
  File "/Users/apple/code/python/virtualsys/blog/lib/python3.5/site-packages/django/db/backends/utils.py", line 64, in execute
    return self.cursor.execute(sql, params)
  File "/Users/apple/code/python/virtualsys/blog/lib/python3.5/site-packages/django/db/backends/sqlite3/base.py", line 318, in execute
    return Database.Cursor.execute(self, query, params)
django.db.utils.OperationalError: no such table: liucl_comments_comment
[2016-06-25 23:15:25,423] [ERROR] base : Internal Server Error: /
Traceback (most recent call last):
  File "/Users/apple/code/python/virtualsys/blog/lib/python3.5/site-packages/django/db/backends/utils.py", line 64, in execute
    return self.cursor.execute(sql, params)
  File "/Users/apple/code/python/virtualsys/blog/lib/python3.5/site-packages/django/db/backends/sqlite3/base.py", line 318, in execute
    return Database.Cursor.execute(self, query, params)
sqlite3.OperationalError: no such table: liucl_comments_comment

The above exception was the direct cause of the following exception:

Traceback (most recent call last):
  File "/Users/apple/code/python/virtualsys/blog/lib/python3.5/site-packages/django/core/handlers/base.py", line 164, in get_response
    response = response.render()
  File "/Users/apple/code/python/virtualsys/blog/lib/python3.5/site-packages/django/template/response.py", line 158, in render
    self.content = self.rendered_content
  File "/Users/apple/code/python/virtualsys/blog/lib/python3.5/site-packages/django/template/response.py", line 135, in rendered_content
    content = template.render(context, self._request)
  File "/Users/apple/code/python/virtualsys/blog/lib/python3.5/site-packages/django/template/backends/django.py", line 74, in render
    return self.template.render(context)
  File "/Users/apple/code/python/virtualsys/blog/lib/python3.5/site-packages/django/template/base.py", line 209, in render
    return self._render(context)
  File "/Users/apple/code/python/virtualsys/blog/lib/python3.5/site-packages/django/template/base.py", line 201, in _render
    return self.nodelist.render(context)
  File "/Users/apple/code/python/virtualsys/blog/lib/python3.5/site-packages/django/template/base.py", line 903, in render
    bit = self.render_node(node, context)
  File "/Users/apple/code/python/virtualsys/blog/lib/python3.5/site-packages/django/template/debug.py", line 79, in render_node
    return node.render(context)
  File "/Users/apple/code/python/virtualsys/blog/lib/python3.5/site-packages/django/template/loader_tags.py", line 135, in render
    return compiled_parent._render(context)
  File "/Users/apple/code/python/virtualsys/blog/lib/python3.5/site-packages/django/template/base.py", line 201, in _render
    return self.nodelist.render(context)
  File "/Users/apple/code/python/virtualsys/blog/lib/python3.5/site-packages/django/template/base.py", line 903, in render
    bit = self.render_node(node, context)
  File "/Users/apple/code/python/virtualsys/blog/lib/python3.5/site-packages/django/template/debug.py", line 79, in render_node
    return node.render(context)
  File "/Users/apple/code/python/virtualsys/blog/lib/python3.5/site-packages/django/template/loader_tags.py", line 65, in render
    result = block.nodelist.render(context)
  File "/Users/apple/code/python/virtualsys/blog/lib/python3.5/site-packages/django/template/base.py", line 903, in render
    bit = self.render_node(node, context)
  File "/Users/apple/code/python/virtualsys/blog/lib/python3.5/site-packages/django/template/debug.py", line 79, in render_node
    return node.render(context)
  File "/Users/apple/code/python/virtualsys/blog/lib/python3.5/site-packages/django/template/defaulttags.py", line 329, in render
    return nodelist.render(context)
  File "/Users/apple/code/python/virtualsys/blog/lib/python3.5/site-packages/django/template/base.py", line 903, in render
    bit = self.render_node(node, context)
  File "/Users/apple/code/python/virtualsys/blog/lib/python3.5/site-packages/django/template/debug.py", line 79, in render_node
    return node.render(context)
  File "/Users/apple/code/python/virtualsys/blog/lib/python3.5/site-packages/django/template/defaulttags.py", line 576, in render
    return self.nodelist.render(context)
  File "/Users/apple/code/python/virtualsys/blog/lib/python3.5/site-packages/django/template/base.py", line 903, in render
    bit = self.render_node(node, context)
  File "/Users/apple/code/python/virtualsys/blog/lib/python3.5/site-packages/django/template/debug.py", line 79, in render_node
    return node.render(context)
  File "/Users/apple/code/python/virtualsys/blog/lib/python3.5/site-packages/django/template/defaulttags.py", line 217, in render
    nodelist.append(node.render(context))
  File "/Users/apple/code/python/virtualsys/blog/lib/python3.5/site-packages/django/template/loader_tags.py", line 159, in render
    return template.render(context)
  File "/Users/apple/code/python/virtualsys/blog/lib/python3.5/site-packages/django/template/base.py", line 211, in render
    return self._render(context)
  File "/Users/apple/code/python/virtualsys/blog/lib/python3.5/site-packages/django/template/base.py", line 201, in _render
    return self.nodelist.render(context)
  File "/Users/apple/code/python/virtualsys/blog/lib/python3.5/site-packages/django/template/base.py", line 903, in render
    bit = self.render_node(node, context)
  File "/Users/apple/code/python/virtualsys/blog/lib/python3.5/site-packages/django/template/debug.py", line 79, in render_node
    return node.render(context)
  File "/Users/apple/code/python/virtualsys/blog/lib/python3.5/site-packages/django/template/debug.py", line 89, in render
    output = self.filter_expression.resolve(context)
  File "/Users/apple/code/python/virtualsys/blog/lib/python3.5/site-packages/django/template/base.py", line 674, in resolve
    new_obj = func(obj, *arg_vals)
  File "/Users/apple/code/python/virtualsys/blog/lib/python3.5/site-packages/django/template/defaultfilters.py", line 582, in length
    return len(value)
  File "/Users/apple/code/python/virtualsys/blog/lib/python3.5/site-packages/django/db/models/query.py", line 144, in __len__
    self._fetch_all()
  File "/Users/apple/code/python/virtualsys/blog/lib/python3.5/site-packages/django/db/models/query.py", line 965, in _fetch_all
    self._result_cache = list(self.iterator())
  File "/Users/apple/code/python/virtualsys/blog/lib/python3.5/site-packages/django/db/models/query.py", line 238, in iterator
    results = compiler.execute_sql()
  File "/Users/apple/code/python/virtualsys/blog/lib/python3.5/site-packages/django/db/models/sql/compiler.py", line 829, in execute_sql
    cursor.execute(sql, params)
  File "/Users/apple/code/python/virtualsys/blog/lib/python3.5/site-packages/django/db/backends/utils.py", line 79, in execute
    return super(CursorDebugWrapper, self).execute(sql, params)
  File "/Users/apple/code/python/virtualsys/blog/lib/python3.5/site-packages/django/db/backends/utils.py", line 64, in execute
    return self.cursor.execute(sql, params)
  File "/Users/apple/code/python/virtualsys/blog/lib/python3.5/site-packages/django/db/utils.py", line 97, in __exit__
    six.reraise(dj_exc_type, dj_exc_value, traceback)
  File "/Users/apple/code/python/virtualsys/blog/lib/python3.5/site-packages/django/utils/six.py", line 658, in reraise
    raise value.with_traceback(tb)
  File "/Users/apple/code/python/virtualsys/blog/lib/python3.5/site-packages/django/db/backends/utils.py", line 64, in execute
    return self.cursor.execute(sql, params)
  File "/Users/apple/code/python/virtualsys/blog/lib/python3.5/site-packages/django/db/backends/sqlite3/base.py", line 318, in execute
    return Database.Cursor.execute(self, query, params)
django.db.utils.OperationalError: no such table: liucl_comments_comment
[2016-06-25 23:17:43,782] [ERROR] base : Internal Server Error: /
Traceback (most recent call last):
  File "/Users/apple/code/python/virtualsys/blog/lib/python3.5/site-packages/django/core/handlers/base.py", line 164, in get_response
    response = response.render()
  File "/Users/apple/code/python/virtualsys/blog/lib/python3.5/site-packages/django/template/response.py", line 158, in render
    self.content = self.rendered_content
  File "/Users/apple/code/python/virtualsys/blog/lib/python3.5/site-packages/django/template/response.py", line 135, in rendered_content
    content = template.render(context, self._request)
  File "/Users/apple/code/python/virtualsys/blog/lib/python3.5/site-packages/django/template/backends/django.py", line 74, in render
    return self.template.render(context)
  File "/Users/apple/code/python/virtualsys/blog/lib/python3.5/site-packages/django/template/base.py", line 209, in render
    return self._render(context)
  File "/Users/apple/code/python/virtualsys/blog/lib/python3.5/site-packages/django/template/base.py", line 201, in _render
    return self.nodelist.render(context)
  File "/Users/apple/code/python/virtualsys/blog/lib/python3.5/site-packages/django/template/base.py", line 903, in render
    bit = self.render_node(node, context)
  File "/Users/apple/code/python/virtualsys/blog/lib/python3.5/site-packages/django/template/debug.py", line 79, in render_node
    return node.render(context)
  File "/Users/apple/code/python/virtualsys/blog/lib/python3.5/site-packages/django/template/loader_tags.py", line 135, in render
    return compiled_parent._render(context)
  File "/Users/apple/code/python/virtualsys/blog/lib/python3.5/site-packages/django/template/base.py", line 201, in _render
    return self.nodelist.render(context)
  File "/Users/apple/code/python/virtualsys/blog/lib/python3.5/site-packages/django/template/base.py", line 903, in render
    bit = self.render_node(node, context)
  File "/Users/apple/code/python/virtualsys/blog/lib/python3.5/site-packages/django/template/debug.py", line 79, in render_node
    return node.render(context)
  File "/Users/apple/code/python/virtualsys/blog/lib/python3.5/site-packages/django/template/loader_tags.py", line 65, in render
    result = block.nodelist.render(context)
  File "/Users/apple/code/python/virtualsys/blog/lib/python3.5/site-packages/django/template/base.py", line 903, in render
    bit = self.render_node(node, context)
  File "/Users/apple/code/python/virtualsys/blog/lib/python3.5/site-packages/django/template/debug.py", line 79, in render_node
    return node.render(context)
  File "/Users/apple/code/python/virtualsys/blog/lib/python3.5/site-packages/django/template/loader_tags.py", line 151, in render
    template = context.template.engine.get_template(template)
  File "/Users/apple/code/python/virtualsys/blog/lib/python3.5/site-packages/django/template/engine.py", line 167, in get_template
    template, origin = self.find_template(template_name, dirs)
  File "/Users/apple/code/python/virtualsys/blog/lib/python3.5/site-packages/django/template/engine.py", line 146, in find_template
    raise TemplateDoesNotExist(name)
django.template.base.TemplateDoesNotExist: ./liucl_comments/latest_comments.html
[2016-06-25 23:17:43,782] [ERROR] base : Internal Server Error: /
Traceback (most recent call last):
  File "/Users/apple/code/python/virtualsys/blog/lib/python3.5/site-packages/django/core/handlers/base.py", line 164, in get_response
    response = response.render()
  File "/Users/apple/code/python/virtualsys/blog/lib/python3.5/site-packages/django/template/response.py", line 158, in render
    self.content = self.rendered_content
  File "/Users/apple/code/python/virtualsys/blog/lib/python3.5/site-packages/django/template/response.py", line 135, in rendered_content
    content = template.render(context, self._request)
  File "/Users/apple/code/python/virtualsys/blog/lib/python3.5/site-packages/django/template/backends/django.py", line 74, in render
    return self.template.render(context)
  File "/Users/apple/code/python/virtualsys/blog/lib/python3.5/site-packages/django/template/base.py", line 209, in render
    return self._render(context)
  File "/Users/apple/code/python/virtualsys/blog/lib/python3.5/site-packages/django/template/base.py", line 201, in _render
    return self.nodelist.render(context)
  File "/Users/apple/code/python/virtualsys/blog/lib/python3.5/site-packages/django/template/base.py", line 903, in render
    bit = self.render_node(node, context)
  File "/Users/apple/code/python/virtualsys/blog/lib/python3.5/site-packages/django/template/debug.py", line 79, in render_node
    return node.render(context)
  File "/Users/apple/code/python/virtualsys/blog/lib/python3.5/site-packages/django/template/loader_tags.py", line 135, in render
    return compiled_parent._render(context)
  File "/Users/apple/code/python/virtualsys/blog/lib/python3.5/site-packages/django/template/base.py", line 201, in _render
    return self.nodelist.render(context)
  File "/Users/apple/code/python/virtualsys/blog/lib/python3.5/site-packages/django/template/base.py", line 903, in render
    bit = self.render_node(node, context)
  File "/Users/apple/code/python/virtualsys/blog/lib/python3.5/site-packages/django/template/debug.py", line 79, in render_node
    return node.render(context)
  File "/Users/apple/code/python/virtualsys/blog/lib/python3.5/site-packages/django/template/loader_tags.py", line 65, in render
    result = block.nodelist.render(context)
  File "/Users/apple/code/python/virtualsys/blog/lib/python3.5/site-packages/django/template/base.py", line 903, in render
    bit = self.render_node(node, context)
  File "/Users/apple/code/python/virtualsys/blog/lib/python3.5/site-packages/django/template/debug.py", line 79, in render_node
    return node.render(context)
  File "/Users/apple/code/python/virtualsys/blog/lib/python3.5/site-packages/django/template/loader_tags.py", line 151, in render
    template = context.template.engine.get_template(template)
  File "/Users/apple/code/python/virtualsys/blog/lib/python3.5/site-packages/django/template/engine.py", line 167, in get_template
    template, origin = self.find_template(template_name, dirs)
  File "/Users/apple/code/python/virtualsys/blog/lib/python3.5/site-packages/django/template/engine.py", line 146, in find_template
    raise TemplateDoesNotExist(name)
django.template.base.TemplateDoesNotExist: ./liucl_comments/latest_comments.html
[2016-06-25 23:20:15,026] [ERROR] base : Internal Server Error: /article/Package.html
Traceback (most recent call last):
  File "/Users/apple/code/python/virtualsys/blog/lib/python3.5/site-packages/django/core/handlers/base.py", line 164, in get_response
    response = response.render()
  File "/Users/apple/code/python/virtualsys/blog/lib/python3.5/site-packages/django/template/response.py", line 158, in render
    self.content = self.rendered_content
  File "/Users/apple/code/python/virtualsys/blog/lib/python3.5/site-packages/django/template/response.py", line 135, in rendered_content
    content = template.render(context, self._request)
  File "/Users/apple/code/python/virtualsys/blog/lib/python3.5/site-packages/django/template/backends/django.py", line 74, in render
    return self.template.render(context)
  File "/Users/apple/code/python/virtualsys/blog/lib/python3.5/site-packages/django/template/base.py", line 209, in render
    return self._render(context)
  File "/Users/apple/code/python/virtualsys/blog/lib/python3.5/site-packages/django/template/base.py", line 201, in _render
    return self.nodelist.render(context)
  File "/Users/apple/code/python/virtualsys/blog/lib/python3.5/site-packages/django/template/base.py", line 903, in render
    bit = self.render_node(node, context)
  File "/Users/apple/code/python/virtualsys/blog/lib/python3.5/site-packages/django/template/debug.py", line 79, in render_node
    return node.render(context)
  File "/Users/apple/code/python/virtualsys/blog/lib/python3.5/site-packages/django/template/loader_tags.py", line 135, in render
    return compiled_parent._render(context)
  File "/Users/apple/code/python/virtualsys/blog/lib/python3.5/site-packages/django/template/base.py", line 201, in _render
    return self.nodelist.render(context)
  File "/Users/apple/code/python/virtualsys/blog/lib/python3.5/site-packages/django/template/base.py", line 903, in render
    bit = self.render_node(node, context)
  File "/Users/apple/code/python/virtualsys/blog/lib/python3.5/site-packages/django/template/debug.py", line 79, in render_node
    return node.render(context)
  File "/Users/apple/code/python/virtualsys/blog/lib/python3.5/site-packages/django/template/loader_tags.py", line 65, in render
    result = block.nodelist.render(context)
  File "/Users/apple/code/python/virtualsys/blog/lib/python3.5/site-packages/django/template/base.py", line 903, in render
    bit = self.render_node(node, context)
  File "/Users/apple/code/python/virtualsys/blog/lib/python3.5/site-packages/django/template/debug.py", line 79, in render_node
    return node.render(context)
  File "/Users/apple/code/python/virtualsys/blog/lib/python3.5/site-packages/django/template/loader_tags.py", line 151, in render
    template = context.template.engine.get_template(template)
  File "/Users/apple/code/python/virtualsys/blog/lib/python3.5/site-packages/django/template/engine.py", line 167, in get_template
    template, origin = self.find_template(template_name, dirs)
  File "/Users/apple/code/python/virtualsys/blog/lib/python3.5/site-packages/django/template/engine.py", line 146, in find_template
    raise TemplateDoesNotExist(name)
django.template.base.TemplateDoesNotExist: ./liucl_comments/liucl_comments.html
[2016-06-25 23:20:15,026] [ERROR] base : Internal Server Error: /article/Package.html
Traceback (most recent call last):
  File "/Users/apple/code/python/virtualsys/blog/lib/python3.5/site-packages/django/core/handlers/base.py", line 164, in get_response
    response = response.render()
  File "/Users/apple/code/python/virtualsys/blog/lib/python3.5/site-packages/django/template/response.py", line 158, in render
    self.content = self.rendered_content
  File "/Users/apple/code/python/virtualsys/blog/lib/python3.5/site-packages/django/template/response.py", line 135, in rendered_content
    content = template.render(context, self._request)
  File "/Users/apple/code/python/virtualsys/blog/lib/python3.5/site-packages/django/template/backends/django.py", line 74, in render
    return self.template.render(context)
  File "/Users/apple/code/python/virtualsys/blog/lib/python3.5/site-packages/django/template/base.py", line 209, in render
    return self._render(context)
  File "/Users/apple/code/python/virtualsys/blog/lib/python3.5/site-packages/django/template/base.py", line 201, in _render
    return self.nodelist.render(context)
  File "/Users/apple/code/python/virtualsys/blog/lib/python3.5/site-packages/django/template/base.py", line 903, in render
    bit = self.render_node(node, context)
  File "/Users/apple/code/python/virtualsys/blog/lib/python3.5/site-packages/django/template/debug.py", line 79, in render_node
    return node.render(context)
  File "/Users/apple/code/python/virtualsys/blog/lib/python3.5/site-packages/django/template/loader_tags.py", line 135, in render
    return compiled_parent._render(context)
  File "/Users/apple/code/python/virtualsys/blog/lib/python3.5/site-packages/django/template/base.py", line 201, in _render
    return self.nodelist.render(context)
  File "/Users/apple/code/python/virtualsys/blog/lib/python3.5/site-packages/django/template/base.py", line 903, in render
    bit = self.render_node(node, context)
  File "/Users/apple/code/python/virtualsys/blog/lib/python3.5/site-packages/django/template/debug.py", line 79, in render_node
    return node.render(context)
  File "/Users/apple/code/python/virtualsys/blog/lib/python3.5/site-packages/django/template/loader_tags.py", line 65, in render
    result = block.nodelist.render(context)
  File "/Users/apple/code/python/virtualsys/blog/lib/python3.5/site-packages/django/template/base.py", line 903, in render
    bit = self.render_node(node, context)
  File "/Users/apple/code/python/virtualsys/blog/lib/python3.5/site-packages/django/template/debug.py", line 79, in render_node
    return node.render(context)
  File "/Users/apple/code/python/virtualsys/blog/lib/python3.5/site-packages/django/template/loader_tags.py", line 151, in render
    template = context.template.engine.get_template(template)
  File "/Users/apple/code/python/virtualsys/blog/lib/python3.5/site-packages/django/template/engine.py", line 167, in get_template
    template, origin = self.find_template(template_name, dirs)
  File "/Users/apple/code/python/virtualsys/blog/lib/python3.5/site-packages/django/template/engine.py", line 146, in find_template
    raise TemplateDoesNotExist(name)
django.template.base.TemplateDoesNotExist: ./liucl_comments/liucl_comments.html
[2016-08-12 12:08:35,878] [ERROR] base : Internal Server Error: /user/notification
Traceback (most recent call last):
  File "/Users/apple/code/python/virtualsys/blog/lib/python3.5/site-packages/django/core/handlers/base.py", line 164, in get_response
    response = response.render()
  File "/Users/apple/code/python/virtualsys/blog/lib/python3.5/site-packages/django/template/response.py", line 158, in render
    self.content = self.rendered_content
  File "/Users/apple/code/python/virtualsys/blog/lib/python3.5/site-packages/django/template/response.py", line 135, in rendered_content
    content = template.render(context, self._request)
  File "/Users/apple/code/python/virtualsys/blog/lib/python3.5/site-packages/django/template/backends/django.py", line 74, in render
    return self.template.render(context)
  File "/Users/apple/code/python/virtualsys/blog/lib/python3.5/site-packages/django/template/base.py", line 209, in render
    return self._render(context)
  File "/Users/apple/code/python/virtualsys/blog/lib/python3.5/site-packages/django/template/base.py", line 201, in _render
    return self.nodelist.render(context)
  File "/Users/apple/code/python/virtualsys/blog/lib/python3.5/site-packages/django/template/base.py", line 903, in render
    bit = self.render_node(node, context)
  File "/Users/apple/code/python/virtualsys/blog/lib/python3.5/site-packages/django/template/debug.py", line 79, in render_node
    return node.render(context)
  File "/Users/apple/code/python/virtualsys/blog/lib/python3.5/site-packages/django/template/loader_tags.py", line 135, in render
    return compiled_parent._render(context)
  File "/Users/apple/code/python/virtualsys/blog/lib/python3.5/site-packages/django/template/base.py", line 201, in _render
    return self.nodelist.render(context)
  File "/Users/apple/code/python/virtualsys/blog/lib/python3.5/site-packages/django/template/base.py", line 903, in render
    bit = self.render_node(node, context)
  File "/Users/apple/code/python/virtualsys/blog/lib/python3.5/site-packages/django/template/debug.py", line 79, in render_node
    return node.render(context)
  File "/Users/apple/code/python/virtualsys/blog/lib/python3.5/site-packages/django/template/loader_tags.py", line 65, in render
    result = block.nodelist.render(context)
  File "/Users/apple/code/python/virtualsys/blog/lib/python3.5/site-packages/django/template/base.py", line 903, in render
    bit = self.render_node(node, context)
  File "/Users/apple/code/python/virtualsys/blog/lib/python3.5/site-packages/django/template/debug.py", line 79, in render_node
    return node.render(context)
  File "/Users/apple/code/python/virtualsys/blog/lib/python3.5/site-packages/django/template/loader_tags.py", line 151, in render
    template = context.template.engine.get_template(template)
  File "/Users/apple/code/python/virtualsys/blog/lib/python3.5/site-packages/django/template/engine.py", line 167, in get_template
    template, origin = self.find_template(template_name, dirs)
  File "/Users/apple/code/python/virtualsys/blog/lib/python3.5/site-packages/django/template/engine.py", line 146, in find_template
    raise TemplateDoesNotExist(name)
django.template.base.TemplateDoesNotExist: ./liucl_auth/notification.html
[2016-08-12 12:08:35,878] [ERROR] base : Internal Server Error: /user/notification
Traceback (most recent call last):
  File "/Users/apple/code/python/virtualsys/blog/lib/python3.5/site-packages/django/core/handlers/base.py", line 164, in get_response
    response = response.render()
  File "/Users/apple/code/python/virtualsys/blog/lib/python3.5/site-packages/django/template/response.py", line 158, in render
    self.content = self.rendered_content
  File "/Users/apple/code/python/virtualsys/blog/lib/python3.5/site-packages/django/template/response.py", line 135, in rendered_content
    content = template.render(context, self._request)
  File "/Users/apple/code/python/virtualsys/blog/lib/python3.5/site-packages/django/template/backends/django.py", line 74, in render
    return self.template.render(context)
  File "/Users/apple/code/python/virtualsys/blog/lib/python3.5/site-packages/django/template/base.py", line 209, in render
    return self._render(context)
  File "/Users/apple/code/python/virtualsys/blog/lib/python3.5/site-packages/django/template/base.py", line 201, in _render
    return self.nodelist.render(context)
  File "/Users/apple/code/python/virtualsys/blog/lib/python3.5/site-packages/django/template/base.py", line 903, in render
    bit = self.render_node(node, context)
  File "/Users/apple/code/python/virtualsys/blog/lib/python3.5/site-packages/django/template/debug.py", line 79, in render_node
    return node.render(context)
  File "/Users/apple/code/python/virtualsys/blog/lib/python3.5/site-packages/django/template/loader_tags.py", line 135, in render
    return compiled_parent._render(context)
  File "/Users/apple/code/python/virtualsys/blog/lib/python3.5/site-packages/django/template/base.py", line 201, in _render
    return self.nodelist.render(context)
  File "/Users/apple/code/python/virtualsys/blog/lib/python3.5/site-packages/django/template/base.py", line 903, in render
    bit = self.render_node(node, context)
  File "/Users/apple/code/python/virtualsys/blog/lib/python3.5/site-packages/django/template/debug.py", line 79, in render_node
    return node.render(context)
  File "/Users/apple/code/python/virtualsys/blog/lib/python3.5/site-packages/django/template/loader_tags.py", line 65, in render
    result = block.nodelist.render(context)
  File "/Users/apple/code/python/virtualsys/blog/lib/python3.5/site-packages/django/template/base.py", line 903, in render
    bit = self.render_node(node, context)
  File "/Users/apple/code/python/virtualsys/blog/lib/python3.5/site-packages/django/template/debug.py", line 79, in render_node
    return node.render(context)
  File "/Users/apple/code/python/virtualsys/blog/lib/python3.5/site-packages/django/template/loader_tags.py", line 151, in render
    template = context.template.engine.get_template(template)
  File "/Users/apple/code/python/virtualsys/blog/lib/python3.5/site-packages/django/template/engine.py", line 167, in get_template
    template, origin = self.find_template(template_name, dirs)
  File "/Users/apple/code/python/virtualsys/blog/lib/python3.5/site-packages/django/template/engine.py", line 146, in find_template
    raise TemplateDoesNotExist(name)
django.template.base.TemplateDoesNotExist: ./liucl_auth/notification.html
